Workbook

Sheet Mekanik Montaj
A1: KONTROL TARİHİ | B1: KONTROL EDİLEN ÜRÜN ADEDİ | C1: HATALI ÜRÜN ADEDİ | D1: P BAR | E1: UCL | F1: LCL | G1: KONTROL
A2: 46029 | B2: 2 | C2: 0 | D2: =C2/B2 -> 0 | E2: =$D$149+3*SQRT($D$149*(1-$D$149)/B2) -> 0.90873615 | F2: =MAX(0,$D$149-3*SQRT($D$149*(1-$D$149)/B2)) -> 0 | G2: =IF(AND(D2<=E2,D2>=F2),"KONTROL İÇİNDE"," KONTROL DIŞINDA") -> KONTROL İÇİNDE
A3: 46030 | B3: 34 | C3: 0 | D3: =C3/B3 -> 0 | E3: =$D$149+3*SQRT($D$149*(1-$D$149)/B3) -> 0.334334 | F3: =MAX(0,$D$149-3*SQRT($D$149*(1-$D$149)/B3)) -> 0 | G3: =IF(AND(D3<=E3,D3>=F3),"KONTROL İÇİNDE"," KONTROL DIŞINDA") -> KONTROL İÇİNDE
A4: 46031 | B4: 1 | C4: 0 | D4: =C4/B4 -> 0 | E4: =$D$149+3*SQRT($D$149*(1-$D$149)/B4) -> 1.2228435 | F4: =MAX(0,$D$149-3*SQRT($D$149*(1-$D$149)/B4)) -> 0 | G4: =IF(AND(D4<=E4,D4>=F4),"KONTROL İÇİNDE"," KONTROL DIŞINDA") -> KONTROL İÇİNDE
A5: 46035 | B5: 81 | C5: 0 | D5: =C5/B5 -> 0 | E5: =$D$149+3*SQRT($D$149*(1-$D$149)/B5) -> 0.26957268 | F5: =MAX(0,$D$149-3*SQRT($D$149*(1-$D$149)/B5)) -> 0.03125496 | G5: =IF(AND(D5<=E5,D5>=F5),"KONTROL İÇİNDE"," KONTROL DIŞINDA") -> KONTROL DIŞINDA
A6: 46037 | B6: 6 | C6: 0 | D6: =C6/B6 -> 0 | E6: =$D$149+3*SQRT($D$149*(1-$D$149)/B6) -> 0.58823142 | F6: =MAX(0,$D$149-3*SQRT($D$149*(1-$D$149)/B6)) -> 0 | G6: =IF(AND(D6<=E6,D6>=F6),"KONTROL İÇİNDE"," KONTROL DIŞINDA") -> KONTROL İÇİNDE
A7: 46038 | B7: 2 | C7: 0 | D7: =C7/B7 -> 0 | E7: =$D$149+3*SQRT($D$149*(1-$D$149)/B7) -> 0.90873615 | F7: =MAX(0,$D$149-3*SQRT($D$149*(1-$D$149)/B7)) -> 0 | G7: =IF(AND(D7<=E7,D7>=F7),"KONTROL İÇİNDE"," KONTROL DIŞINDA") -> KONTROL İÇİNDE
A8: 46041 | B8: 12 | C8: 0 | D8: =C8/B8 -> 0 | E8: =$D$149+3*SQRT($D$149*(1-$D$149)/B8) -> 0.45999761 | F8: =MAX(0,$D$149-3*SQRT($D$149*(1-$D$149)/B8)) -> 0 | G8: =IF(AND(D8<=E8,D8>=F8),"KONTROL İÇİNDE"," KONTROL DIŞINDA") -> KONTROL İÇİNDE
A9: 46043 | B9: 316 | C9: 0 | D9: =C9/B9 -> 0 | E9: =$D$149+3*SQRT($D$149*(1-$D$149)/B9) -> 0.2107427 | F9: =MAX(0,$D$149-3*SQRT($D$149*(1-$D$149)/B9)) -> 0.090084933 | G9: =IF(AND(D9<=E9,D9>=F9),"KONTROL İÇİNDE"," KONTROL DIŞINDA") -> KONTROL DIŞINDA
A10: 46045 | B10: 9 | C10: 1 | D10: =C10/B10 -> 0.11111111 | E10: =$D$149+3*SQRT($D$149*(1-$D$149)/B10) -> 0.50789039 | F10: =MAX(0,$D$149-3*SQRT($D$149*(1-$D$149)/B10)) -> 0 | G10: =IF(AND(D10<=E10,D10>=F10),"KONTROL İÇİNDE"," KONTROL DIŞINDA") -> KONTROL İÇİNDE
A11: 46048 | B11: 2 | C11: 0 | D11: =C11/B11 -> 0 | E11: =$D$149+3*SQRT($D$149*(1-$D$149)/B11) -> 0.90873615 | F11: =MAX(0,$D$149-3*SQRT($D$149*(1-$D$149)/B11)) -> 0 | G11: =IF(AND(D11<=E11,D11>=F11),"KONTROL İÇİNDE"," KONTROL DIŞINDA") -> KONTROL İÇİNDE
A12: 46050 | B12: 205 | C12: 0 | D12: =C12/B12 -> 0 | E12: =$D$149+3*SQRT($D$149*(1-$D$149)/B12) -> 0.22531556 | F12: =MAX(0,$D$149-3*SQRT($D$149*(1-$D$149)/B12)) -> 0.075512077 | G12: =IF(AND(D12<=E12,D12>=F12),"KONTROL İÇİNDE"," KONTROL DIŞINDA") -> KONTROL DIŞINDA
A13: 46052 | B13: 6 | C13: 0 | D13: =C13/B13 -> 0 | E13: =$D$149+3*SQRT($D$149*(1-$D$149)/B13) -> 0.58823142 | F13: =MAX(0,$D$149-3*SQRT($D$149*(1-$D$149)/B13)) -> 0 | G13: =IF(AND(D13<=E13,D13>=F13),"KONTROL İÇİNDE"," KONTROL DIŞINDA") -> KONTROL İÇİNDE
... A25: 46070 | B25: 11 | C25: 0 | D25: =C25/B25 -> 0 | E25: =$D$149+3*SQRT($D$149*(1-$D$149)/B25) -> 0.47376355 | F25: =MAX(0,$D$149-3*SQRT($D$149*(1-$D$149)/B25)) -> 0 | G25: =IF(AND(D25<=E25,D25>=F25),"KONTROL İÇİNDE"," KONTROL DIŞINDA") -> KONTROL İÇİNDE
A26: 46071 | B26: 806 | C26: 800 | D26: =C26/B26 -> 0.99255583 | E26: =$D$149+3*SQRT($D$149*(1-$D$149)/B26) -> 0.18818854 | F26: =MAX(0,$D$149-3*SQRT($D$149*(1-$D$149)/B26)) -> 0.11263909 | G26: =IF(AND(D26<=E26,D26>=F26),"KONTROL İÇİNDE"," KONTROL DIŞINDA") -> KONTROL DIŞINDA | H26: Enjeksiyon Kısımlarında Oynama Var
A27: 46072 | B27: 8 | C27: 0 | D27: =C27/B27 -> 0 | E27: =$D$149+3*SQRT($D$149*(1-$D$149)/B27) -> 0.52957498 | F27: =MAX(0,$D$149-3*SQRT($D$149*(1-$D$149)/B27)) -> 0 | G27: =IF(AND(D27<=E27,D27>=F27),"KONTROL İÇİNDE"," KONTROL DIŞINDA") -> KONTROL İÇİNDE
A28: 46076 | B28: 12 | C28: 0 | D28: =C28/B28 -> 0 | E28: =$D$149+3*SQRT($D$149*(1-$D$149)/B28) -> 0.45999761 | F28: =MAX(0,$D$149-3*SQRT($D$149*(1-$D$149)/B28)) -> 0 | G28: =IF(AND(D28<=E28,D28>=F28),"KONTROL İÇİNDE"," KONTROL DIŞINDA") -> KONTROL İÇİNDE
A29: 46077 | B29: 5 | C29: 0 | D29: =C29/B29 -> 0 | E29: =$D$149+3*SQRT($D$149*(1-$D$149)/B29) -> 0.63001897 | F29: =MAX(0,$D$149-3*SQRT($D$149*(1-$D$149)/B29)) -> 0 | G29: =IF(AND(D29<=E29,D29>=F29),"KONTROL İÇİNDE"," KONTROL DIŞINDA") -> KONTROL İÇİNDE
A30: 46078 | B30: 3 | C30: 0 | D30: =C30/B30 -> 0 | E30: =$D$149+3*SQRT($D$149*(1-$D$149)/B30) -> 0.76958141 | F30: =MAX(0,$D$149-3*SQRT($D$149*(1-$D$149)/B30)) -> 0 | G30: =IF(AND(D30<=E30,D30>=F30),"KONTROL İÇİNDE"," KONTROL DIŞINDA") -> KONTROL İÇİNDE
A31: 46079 | B31: 2 | C31: 0 | D31: =C31/B31 -> 0 | E31: =$D$149+3*SQRT($D$149*(1-$D$149)/B31) -> 0.90873615 | F31: =MAX(0,$D$149-3*SQRT($D$149*(1-$D$149)/B31)) -> 0 | G31: =IF(AND(D31<=E31,D31>=F31),"KONTROL İÇİNDE"," KONTROL DIŞINDA") -> KONTROL İÇİNDE
A32: 46081 | B32: 28 | C32: 0 | D32: =C32/B32 -> 0 | E32: =$D$149+3*SQRT($D$149*(1-$D$149)/B32) -> 0.35308399 | F32: =MAX(0,$D$149-3*SQRT($D$149*(1-$D$149)/B32)) -> 0 | G32: =IF(AND(D32<=E32,D32>=F32),"KONTROL İÇİNDE"," KONTROL DIŞINDA") -> KONTROL İÇİNDE
A33: 46083 | B33: 2 | C33: 0 | D33: =C33/B33 -> 0 | E33: =$D$149+3*SQRT($D$149*(1-$D$149)/B33) -> 0.90873615 | F33: =MAX(0,$D$149-3*SQRT($D$149*(1-$D$149)/B33)) -> 0 | G33: =IF(AND(D33<=E33,D33>=F33),"KONTROL İÇİNDE"," KONTROL DIŞINDA") -> KONTROL İÇİNDE
A34: 46084 | B34: 134 | C34: 1 | D34: =C34/B34 -> 0.0074626866 | E34: =$D$149+3*SQRT($D$149*(1-$D$149)/B34) -> 0.24305764 | F34: =MAX(0,$D$149-3*SQRT($D$149*(1-$D$149)/B34)) -> 0.05777 | G34: =IF(AND(D34<=E34,D34>=F34),"KONTROL İÇİNDE"," KONTROL DIŞINDA") -> KONTROL DIŞINDA
A35: 46086 | B35: 113 | C35: 3 | D35: =C35/B35 -> 0.026548673 | E35: =$D$149+3*SQRT($D$149*(1-$D$149)/B35) -> 0.25129952 | F35: =MAX(0,$D$149-3*SQRT($D$149*(1-$D$149)/B35)) -> 0.049528116 | G35: =IF(AND(D35<=E35,D35>=F35),"KONTROL İÇİNDE"," KONTROL DIŞINDA") -> KONTROL DIŞINDA
A36: 46086 | B36: 59 | C36: 0 | D36: =C36/B36 -> 0 | E36: =$D$149+3*SQRT($D$149*(1-$D$149)/B36) -> 0.29003228 | F36: =MAX(0,$D$149-3*SQRT($D$149*(1-$D$149)/B36)) -> 0.01079536 | G36: =IF(AND(D36<=E36,D36>=F36),"KONTROL İÇİNDE"," KONTROL DIŞINDA") -> KONTROL DIŞINDA
A37: 46087 | B37: 2 | C37: 0 | D37: =C37/B37 -> 0 | E37: =$D$149+3*SQRT($D$149*(1-$D$149)/B37) -> 0.90873615 | F37: =MAX(0,$D$149-3*SQRT($D$149*(1-$D$149)/B37)) -> 0 | G37: =IF(AND(D37<=E37,D37>=F37),"KONTROL İÇİNDE"," KONTROL DIŞINDA") -> KONTROL İÇİNDE
A38: 46090 | B38: 2 | C38: 0 | D38: =C38/B38 -> 0 | E38: =$D$149+3*SQRT($D$149*(1-$D$149)/B38) -> 0.90873615 | F38: =MAX(0,$D$149-3*SQRT($D$149*(1-$D$149)/B38)) -> 0 | G38: =IF(AND(D38<=E38,D38>=F38),"KONTROL İÇİNDE"," KONTROL DIŞINDA") -> KONTROL İÇİNDE
... A148: 46262 | B148: 57 | C148: 0 | D148: =C148/B148 -> 0 | E148: =$D$149+3*SQRT($D$149*(1-$D$149)/B148) -> 0.2924606 | F148: =MAX(0,$D$149-3*SQRT($D$149*(1-$D$149)/B148)) -> 0.008367031 | G148: =IF(AND(D148<=E148,D148>=F148),"KONTROL İÇİNDE"," KONTROL DIŞINDA") -> KONTROL DIŞINDA
B149: =SUM(B2:B148) -> 5558 | C149: =SUM(C2:C148) -> 836 | D149: =C149/B149 -> 0.15041382

Sheet Mekanik Dyson Hatası
A1: KONTROL TARİHİ | B1: KONTROL EDİLEN ÜRÜN ADEDİ | C1: Hatalı Üürn adedi | D1: P BAR | E1: UCL | F1: LCL | G1: KONTROL
A2: 46029 | B2: 2 | C2: 0 | D2: =C2/B2 -> 0 | E2: =$D$152+3*SQRT($D$152*(1-$D$152)/B2) -> 0.67940999 | F2: =MAX(0,$D$152-3*SQRT($D$152*(1-$D$152)/B2)) -> 0 | G2: =IF(AND(D2<=E2,D2>=F2),"KONTROL İÇİNDE"," KONTROL DIŞINDA") -> KONTROL İÇİNDE
A3: 46030 | B3: 34 | C3: 0 | D3: =C3/B3 -> 0 | E3: =$D$152+3*SQRT($D$152*(1-$D$152)/B3) -> 0.22967914 | F3: =MAX(0,$D$152-3*SQRT($D$152*(1-$D$152)/B3)) -> 0 | G3: =IF(AND(D3<=E3,D3>=F3),"KONTROL İÇİNDE"," KONTROL DIŞINDA") -> KONTROL İÇİNDE
A4: 46031 | B4: 1 | C4: 0 | D4: =C4/B4 -> 0 | E4: =$D$152+3*SQRT($D$152*(1-$D$152)/B4) -> 0.92534183 | F4: =MAX(0,$D$152-3*SQRT($D$152*(1-$D$152)/B4)) -> 0 | G4: =IF(AND(D4<=E4,D4>=F4),"KONTROL İÇİNDE"," KONTROL DIŞINDA") -> KONTROL İÇİNDE
A5: 46034 | B5: 30 | C5: 11 | D5: =C5/B5 -> 0.36666667 | E5: =$D$152+3*SQRT($D$152*(1-$D$152)/B5) -> 0.23897893 | F5: =MAX(0,$D$152-3*SQRT($D$152*(1-$D$152)/B5)) -> 0 | G5: =IF(AND(D5<=E5,D5>=F5),"KONTROL İÇİNDE"," KONTROL DIŞINDA") -> KONTROL DIŞINDA | H5: Dayson Hatası
A6: 46035 | B6: 81 | C6: 0 | D6: =C6/B6 -> 0 | E6: =$D$152+3*SQRT($D$152*(1-$D$152)/B6) -> 0.17897397 | F6: =MAX(0,$D$152-3*SQRT($D$152*(1-$D$152)/B6)) -> 0 | G6: =IF(AND(D6<=E6,D6>=F6),"KONTROL İÇİNDE"," KONTROL DIŞINDA") -> KONTROL İÇİNDE
A7: 46037 | B7: 6 | C7: 0 | D7: =C7/B7 -> 0 | E7: =$D$152+3*SQRT($D$152*(1-$D$152)/B7) -> 0.42846931 | F7: =MAX(0,$D$152-3*SQRT($D$152*(1-$D$152)/B7)) -> 0 | G7: =IF(AND(D7<=E7,D7>=F7),"KONTROL İÇİNDE"," KONTROL DIŞINDA") -> KONTROL İÇİNDE
A8: 46038 | B8: 2 | C8: 0 | D8: =C8/B8 -> 0 | E8: =$D$152+3*SQRT($D$152*(1-$D$152)/B8) -> 0.67940999 | F8: =MAX(0,$D$152-3*SQRT($D$152*(1-$D$152)/B8)) -> 0 | G8: =IF(AND(D8<=E8,D8>=F8),"KONTROL İÇİNDE"," KONTROL DIŞINDA") -> KONTROL İÇİNDE
A9: 46041 | B9: 12 | C9: 0 | D9: =C9/B9 -> 0 | E9: =$D$152+3*SQRT($D$152*(1-$D$152)/B9) -> 0.32806806 | F9: =MAX(0,$D$152-3*SQRT($D$152*(1-$D$152)/B9)) -> 0 | G9: =IF(AND(D9<=E9,D9>=F9),"KONTROL İÇİNDE"," KONTROL DIŞINDA") -> KONTROL İÇİNDE
A10: 46043 | B10: 316 | C10: 0 | D10: =C10/B10 -> 0 | E10: =$D$152+3*SQRT($D$152*(1-$D$152)/B10) -> 0.13291276 | F10: =MAX(0,$D$152-3*SQRT($D$152*(1-$D$152)/B10)) -> 0.038443199 | G10: =IF(AND(D10<=E10,D10>=F10),"KONTROL İÇİNDE"," KONTROL DIŞINDA") -> KONTROL DIŞINDA
A11: 46045 | B11: 9 | C11: 1 | D11: =C11/B11 -> 0.11111111 | E11: =$D$152+3*SQRT($D$152*(1-$D$152)/B11) -> 0.36556593 | F11: =MAX(0,$D$152-3*SQRT($D$152*(1-$D$152)/B11)) -> 0 | G11: =IF(AND(D11<=E11,D11>=F11),"KONTROL İÇİNDE"," KONTROL DIŞINDA") -> KONTROL İÇİNDE
A12: 46048 | B12: 2 | C12: 0 | D12: =C12/B12 -> 0 | E12: =$D$152+3*SQRT($D$152*(1-$D$152)/B12) -> 0.67940999 | F12: =MAX(0,$D$152-3*SQRT($D$152*(1-$D$152)/B12)) -> 0 | G12: =IF(AND(D12<=E12,D12>=F12),"KONTROL İÇİNDE"," KONTROL DIŞINDA") -> KONTROL İÇİNDE
A13: 46050 | B13: 205 | C13: 0 | D13: =C13/B13 -> 0 | E13: =$D$152+3*SQRT($D$152*(1-$D$152)/B13) -> 0.14432265 | F13: =MAX(0,$D$152-3*SQRT($D$152*(1-$D$152)/B13)) -> 0.027033314 | G13: =IF(AND(D13<=E13,D13>=F13),"KONTROL İÇİNDE"," KONTROL DIŞINDA") -> KONTROL DIŞINDA
A14: 46052 | B14: 6 | C14: 0 | D14: =C14/B14 -> 0 | E14: =$D$152+3*SQRT($D$152*(1-$D$152)/B14) -> 0.42846931 | F14: =MAX(0,$D$152-3*SQRT($D$152*(1-$D$152)/B14)) -> 0 | G14: =IF(AND(D14<=E14,D14>=F14),"KONTROL İÇİNDE"," KONTROL DIŞINDA") -> KONTROL İÇİNDE
A15: 46055 | B15: 2 | C15: 0 | D15: =C15/B15 -> 0 | E15: =$D$152+3*SQRT($D$152*(1-$D$152)/B15) -> 0.67940999 | F15: =MAX(0,$D$152-3*SQRT($D$152*(1-$D$152)/B15)) -> 0 | G15: =IF(AND(D15<=E15,D15>=F15),"KONTROL İÇİNDE"," KONTROL DIŞINDA") -> KONTROL İÇİNDE
A16: 46056 | B16: 1 | C16: 0 | D16: =C16/B16 -> 0 | E16: =$D$152+3*SQRT($D$152*(1-$D$152)/B16) -> 0.92534183 | F16: =MAX(0,$D$152-3*SQRT($D$152*(1-$D$152)/B16)) -> 0 | G16: =IF(AND(D16<=E16,D16>=F16),"KONTROL İÇİNDE"," KONTROL DIŞINDA") -> KONTROL İÇİNDE
A17: 46057 | B17: 7 | C17: 0 | D17: =C17/B17 -> 0 | E17: =$D$152+3*SQRT($D$152*(1-$D$152)/B17) -> 0.40304109 | F17: =MAX(0,$D$152-3*SQRT($D$152*(1-$D$152)/B17)) -> 0 | G17: =IF(AND(D17<=E17,D17>=F17),"KONTROL İÇİNDE"," KONTROL DIŞINDA") -> KONTROL İÇİNDE
... A28: 46072 | B28: 8 | C28: 0 | D28: =C28/B28 -> 0 | E28: =$D$152+3*SQRT($D$152*(1-$D$152)/B28) -> 0.38254398 | F28: =MAX(0,$D$152-3*SQRT($D$152*(1-$D$152)/B28)) -> 0 | G28: =IF(AND(D28<=E28,D28>=F28),"KONTROL İÇİNDE"," KONTROL DIŞINDA") -> KONTROL İÇİNDE
A29: 46076 | B29: 42 | C29: 28 | D29: =C29/B29 -> 0.66666667 | E29: =$D$152+3*SQRT($D$152*(1-$D$152)/B29) -> 0.21524093 | F29: =MAX(0,$D$152-3*SQRT($D$152*(1-$D$152)/B29)) -> 0 | G29: =IF(AND(D29<=E29,D29>=F29),"KONTROL İÇİNDE"," KONTROL DIŞINDA") -> KONTROL DIŞINDA | H29: Dayson Hatası
A30: 46077 | B30: 5 | C30: 0 | D30: =C30/B30 -> 0 | E30: =$D$152+3*SQRT($D$152*(1-$D$152)/B30) -> 0.46118707 | F30: =MAX(0,$D$152-3*SQRT($D$152*(1-$D$152)/B30)) -> 0 | G30: =IF(AND(D30<=E30,D30>=F30),"KONTROL İÇİNDE"," KONTROL DIŞINDA") -> KONTROL İÇİNDE
A31: 46078 | B31: 103 | C31: 65 | D31: =C31/B31 -> 0.63106796 | E31: =$D$152+3*SQRT($D$152*(1-$D$152)/B31) -> 0.16841252 | F31: =MAX(0,$D$152-3*SQRT($D$152*(1-$D$152)/B31)) -> 0.0029434437 | G31: =IF(AND(D31<=E31,D31>=F31),"KONTROL İÇİNDE"," KONTROL DIŞINDA") -> KONTROL DIŞINDA | H31: Dayson Hatası
A32: 46079 | B32: 102 | C32: 60 | D32: =C32/B32 -> 0.58823529 | E32: =$D$152+3*SQRT($D$152*(1-$D$152)/B32) -> 0.16881709 | F32: =MAX(0,$D$152-3*SQRT($D$152*(1-$D$152)/B32)) -> 0.0025388715 | G32: =IF(AND(D32<=E32,D32>=F32),"KONTROL İÇİNDE"," KONTROL DIŞINDA") -> KONTROL DIŞINDA | H32: Dayson Hatası
A33: 46081 | B33: 28 | C33: 0 | D33: =C33/B33 -> 0 | E33: =$D$152+3*SQRT($D$152*(1-$D$152)/B33) -> 0.24435953 | F33: =MAX(0,$D$152-3*SQRT($D$152*(1-$D$152)/B33)) -> 0 | G33: =IF(AND(D33<=E33,D33>=F33),"KONTROL İÇİNDE"," KONTROL DIŞINDA") -> KONTROL İÇİNDE
A34: 46083 | B34: 2 | C34: 0 | D34: =C34/B34 -> 0 | E34: =$D$152+3*SQRT($D$152*(1-$D$152)/B34) -> 0.67940999 | F34: =MAX(0,$D$152-3*SQRT($D$152*(1-$D$152)/B34)) -> 0 | G34: =IF(AND(D34<=E34,D34>=F34),"KONTROL İÇİNDE"," KONTROL DIŞINDA") -> KONTROL İÇİNDE
A35: 46084 | B35: 233 | C35: 4 | D35: =C35/B35 -> 0.017167382 | E35: =$D$152+3*SQRT($D$152*(1-$D$152)/B35) -> 0.14068619 | F35: =MAX(0,$D$152-3*SQRT($D$152*(1-$D$152)/B35)) -> 0.030669774 | G35: =IF(AND(D35<=E35,D35>=F35),"KONTROL İÇİNDE"," KONTROL DIŞINDA") -> KONTROL DIŞINDA | H35: Dayson Hatası
A36: 46086 | B36: 5 | C36: 0 | D36: =C36/B36 -> 0 | E36: =$D$152+3*SQRT($D$152*(1-$D$152)/B36) -> 0.46118707 | F36: =MAX(0,$D$152-3*SQRT($D$152*(1-$D$152)/B36)) -> 0 | G36: =IF(AND(D36<=E36,D36>=F36),"KONTROL İÇİNDE"," KONTROL DIŞINDA") -> KONTROL İÇİNDE
A37: 46087 | B37: 2 | C37: 0 | D37: =C37/B37 -> 0 | E37: =$D$152+3*SQRT($D$152*(1-$D$152)/B37) -> 0.67940999 | F37: =MAX(0,$D$152-3*SQRT($D$152*(1-$D$152)/B37)) -> 0 | G37: =IF(AND(D37<=E37,D37>=F37),"KONTROL İÇİNDE"," KONTROL DIŞINDA") -> KONTROL İÇİNDE
A38: 46090 | B38: 2 | C38: 0 | D38: =C38/B38 -> 0 | E38: =$D$152+3*SQRT($D$152*(1-$D$152)/B38) -> 0.67940999 | F38: =MAX(0,$D$152-3*SQRT($D$152*(1-$D$152)/B38)) -> 0 | G38: =IF(AND(D38<=E38,D38>=F38),"KONTROL İÇİNDE"," KONTROL DIŞINDA") -> KONTROL İÇİNDE
A39: 46091 | B39: 102 | C39: 52 | D39: =C39/B39 -> 0.50980392 | E39: =$D$152+3*SQRT($D$152*(1-$D$152)/B39) -> 0.16881709 | F39: =MAX(0,$D$152-3*SQRT($D$152*(1-$D$152)/B39)) -> 0.0025388715 | G39: =IF(AND(D39<=E39,D39>=F39),"KONTROL İÇİNDE"," KONTROL DIŞINDA") -> KONTROL DIŞINDA | H39: Dayson Hatası
A40: 46092 | B40: 9 | C40: 0 | D40: =C40/B40 -> 0 | E40: =$D$152+3*SQRT($D$152*(1-$D$152)/B40) -> 0.36556593 | F40: =MAX(0,$D$152-3*SQRT($D$152*(1-$D$152)/B40)) -> 0 | G40: =IF(AND(D40<=E40,D40>=F40),"KONTROL İÇİNDE"," KONTROL DIŞINDA") -> KONTROL İÇİNDE
A41: 46093 | B41: 23 | C41: 0 | D41: =C41/B41 -> 0 | E41: =$D$152+3*SQRT($D$152*(1-$D$152)/B41) -> 0.26076 | F41: =MAX(0,$D$152-3*SQRT($D$152*(1-$D$152)/B41)) -> 0 | G41: =IF(AND(D41<=E41,D41>=F41),"KONTROL İÇİNDE"," KONTROL DIŞINDA") -> KONTROL İÇİNDE
A42: 46094 | B42: 1 | C42: 0 | D42: =C42/B42 -> 0 | E42: =$D$152+3*SQRT($D$152*(1-$D$152)/B42) -> 0.92534183 | F42: =MAX(0,$D$152-3*SQRT($D$152*(1-$D$152)/B42)) -> 0 | G42: =IF(AND(D42<=E42,D42>=F42),"KONTROL İÇİNDE"," KONTROL DIŞINDA") -> KONTROL İÇİNDE
A43: 46096 | B43: 1 | C43: 0 | D43: =C43/B43 -> 0 | E43: =$D$152+3*SQRT($D$152*(1-$D$152)/B43) -> 0.92534183 | F43: =MAX(0,$D$152-3*SQRT($D$152*(1-$D$152)/B43)) -> 0 | G43: =IF(AND(D43<=E43,D43>=F43),"KONTROL İÇİNDE"," KONTROL DIŞINDA") -> KONTROL İÇİNDE
A44: 46097 | B44: 33 | C44: 0 | D44: =C44/B44 -> 0 | E44: =$D$152+3*SQRT($D$152*(1-$D$152)/B44) -> 0.2318447 | F44: =MAX(0,$D$152-3*SQRT($D$152*(1-$D$152)/B44)) -> 0 | G44: =IF(AND(D44<=E44,D44>=F44),"KONTROL İÇİNDE"," KONTROL DIŞINDA") -> KONTROL İÇİNDE
A45: 46098 | B45: 17 | C45: 0 | D45: =C45/B45 -> 0 | E45: =$D$152+3*SQRT($D$152*(1-$D$152)/B45) -> 0.28932638 | F45: =MAX(0,$D$152-3*SQRT($D$152*(1-$D$152)/B45)) -> 0 | G45: =IF(AND(D45<=E45,D45>=F45),"KONTROL İÇİNDE"," KONTROL DIŞINDA") -> KONTROL İÇİNDE
A46: 46099 | B46: 30 | C46: 0 | D46: =C46/B46 -> 0 | E46: =$D$152+3*SQRT($D$152*(1-$D$152)/B46) -> 0.23897893 | F46: =MAX(0,$D$152-3*SQRT($D$152*(1-$D$152)/B46)) -> 0 | G46: =IF(AND(D46<=E46,D46>=F46),"KONTROL İÇİNDE"," KONTROL DIŞINDA") -> KONTROL İÇİNDE
A47: 46101 | B47: 1 | C47: 0 | D47: =C47/B47 -> 0 | E47: =$D$152+3*SQRT($D$152*(1-$D$152)/B47) -> 0.92534183 | F47: =MAX(0,$D$152-3*SQRT($D$152*(1-$D$152)/B47)) -> 0 | G47: =IF(AND(D47<=E47,D47>=F47),"KONTROL İÇİNDE"," KONTROL DIŞINDA") -> KONTROL İÇİNDE
A48: 46104 | B48: 50 | C48: 30 | D48: =C48/B48 -> 0.6 | E48: =$D$152+3*SQRT($D$152*(1-$D$152)/B48) -> 0.20442438 | F48: =MAX(0,$D$152-3*SQRT($D$152*(1-$D$152)/B48)) -> 0 | G48: =IF(AND(D48<=E48,D48>=F48),"KONTROL İÇİNDE"," KONTROL DIŞINDA") -> KONTROL DIŞINDA | H48: Dayson Hatası
A49: 46105 | B49: 165 | C49: 55 | D49: =C49/B49 -> 0.33333333 | E49: =$D$152+3*SQRT($D$152*(1-$D$152)/B49) -> 0.15104572 | F49: =MAX(0,$D$152-3*SQRT($D$152*(1-$D$152)/B49)) -> 0.020310239 | G49: =IF(AND(D49<=E49,D49>=F49),"KONTROL İÇİNDE"," KONTROL DIŞINDA") -> KONTROL DIŞINDA | H49: Dayson Hatası
A50: 46106 | B50: 120 | C50: 43 | D50: =C50/B50 -> 0.35833333 | E50: =$D$152+3*SQRT($D$152*(1-$D$152)/B50) -> 0.16232845 | F50: =MAX(0,$D$152-3*SQRT($D$152*(1-$D$152)/B50)) -> 0.0090275094 | G50: =IF(AND(D50<=E50,D50>=F50),"KONTROL İÇİNDE"," KONTROL DIŞINDA") -> KONTROL DIŞINDA | H50: Dayson Hatası
...

Sheet Kozmetik Hata
A1: AY | B1: KONTROL TARİHİ | C1: ÜRÜN GRUBU | D1: KONTROL EDİLEN ÜRÜN ADEDİ | E1: HATALI ÜRÜN ADEDİ | F1: P BAR | G1: UCL | H1: LCL | I1: KONTROL
A2: OCAK | B2: 46028 | C2: 4 | D2: 4 | E2: 2 | F2: =E2/D2 -> 0.5 | G2: =$F$152+3*SQRT($F$152*(1-$F$152)/D2) -> 0.17194422 | H2: =MAX(0,$F$152-3*SQRT($F$152*(1-$F$152)/D2)) -> 0 | I2: =IF(AND(F2<=G2,F2>=H2),"KONTROL İÇİNDE"," KONTROL DIŞINDA") -> KONTROL DIŞINDA | J2: 2 Adet albedo kutudaki çizikten dolayı değiştirildi
A3: OCAK | B3: 46029 | C3: 2 | D3: 2 | E3: 0 | F3: =E3/D3 -> 0 | G3: =$F$152+3*SQRT($F$152*(1-$F$152)/D3) -> 0.23837528 | H3: =MAX(0,$F$152-3*SQRT($F$152*(1-$F$152)/D3)) -> 0 | I3: =IF(AND(F3<=G3,F3>=H3),"KONTROL İÇİNDE"," KONTROL DIŞINDA") -> KONTROL İÇİNDE
A4: OCAK | B4: 46030 | C4: 34 | D4: 34 | E4: 0 | F4: =E4/D4 -> 0 | G4: =$F$152+3*SQRT($F$152*(1-$F$152)/D4) -> 0.066574928 | H4: =MAX(0,$F$152-3*SQRT($F$152*(1-$F$152)/D4)) -> 0 | I4: =IF(AND(F4<=G4,F4>=H4),"KONTROL İÇİNDE"," KONTROL DIŞINDA") -> KONTROL İÇİNDE
A5: OCAK | B5: 46031 | C5: 4 | D5: 4 | E5: 1 | F5: =E5/D5 -> 0.25 | G5: =$F$152+3*SQRT($F$152*(1-$F$152)/D5) -> 0.17194422 | H5: =MAX(0,$F$152-3*SQRT($F$152*(1-$F$152)/D5)) -> 0 | I5: =IF(AND(F5<=G5,F5>=H5),"KONTROL İÇİNDE"," KONTROL DIŞINDA") -> KONTROL DIŞINDA | J5: Yön Kablosu Üzerinde Derin Kesik ve Ezik İzleri Var Furkan Cnabay ın Onayı Gitti -Üretim Hatası
A6: OCAK | B6: 46034 | C6: 2 | D6: 2 | E6: 2 | F6: =E6/D6 -> 1 | G6: =$F$152+3*SQRT($F$152*(1-$F$152)/D6) -> 0.23837528 | H6: =MAX(0,$F$152-3*SQRT($F$152*(1-$F$152)/D6)) -> 0 | I6: =IF(AND(F6<=G6,F6>=H6),"KONTROL İÇİNDE"," KONTROL DIŞINDA") -> KONTROL DIŞINDA | J6: Ürünlerin Mekanik Yapısında Çizik Var Furkan Canbay ın Onayı İle Gitti
A7: ŞUBAT | B7: 46035 | C7: 81 | D7: 81 | E7: 0 | F7: =E7/D7 -> 0 | G7: =$F$152+3*SQRT($F$152*(1-$F$152)/D7) -> 0.047205192 | H7: =MAX(0,$F$152-3*SQRT($F$152*(1-$F$152)/D7)) -> 0 | I7: =IF(AND(F7<=G7,F7>=H7),"KONTROL İÇİNDE"," KONTROL DIŞINDA") -> KONTROL İÇİNDE
A8: ŞUBAT | B8: 46036 | C8: 34 | D8: 34 | E8: 2 | F8: =E8/D8 -> 0.058823529 | G8: =$F$152+3*SQRT($F$152*(1-$F$152)/D8) -> 0.066574928 | H8: =MAX(0,$F$152-3*SQRT($F$152*(1-$F$152)/D8)) -> 0 | I8: =IF(AND(F8<=G8,F8>=H8),"KONTROL İÇİNDE"," KONTROL DIŞINDA") -> KONTROL İÇİNDE
A9: MART | B9: 46037 | C9: 6 | D9: 6 | E9: 0 | F9: =E9/D9 -> 0 | G9: =$F$152+3*SQRT($F$152*(1-$F$152)/D9) -> 0.14251417 | H9: =MAX(0,$F$152-3*SQRT($F$152*(1-$F$152)/D9)) -> 0 | I9: =IF(AND(F9<=G9,F9>=H9),"KONTROL İÇİNDE"," KONTROL DIŞINDA") -> KONTROL İÇİNDE
A10: MART | B10: 46038 | C10: 2 | D10: 2 | E10: 0 | F10: =E10/D10 -> 0 | G10: =$F$152+3*SQRT($F$152*(1-$F$152)/D10) -> 0.23837528 | H10: =MAX(0,$F$152-3*SQRT($F$152*(1-$F$152)/D10)) -> 0 | I10: =IF(AND(F10<=G10,F10>=H10),"KONTROL İÇİNDE"," KONTROL DIŞINDA") -> KONTROL İÇİNDE
A11: MART | B11: 46041 | C11: 14 | D11: 14 | E11: 2 | F11: =E11/D11 -> 0.14285714 | G11: =$F$152+3*SQRT($F$152*(1-$F$152)/D11) -> 0.097291519 | H11: =MAX(0,$F$152-3*SQRT($F$152*(1-$F$152)/D11)) -> 0 | I11: =IF(AND(F11<=G11,F11>=H11),"KONTROL İÇİNDE"," KONTROL DIŞINDA") -> KONTROL DIŞINDA | J11: Mekanik Yapıda Çizik Var Furkan Canbay ın Onayı İle Gitti-Sertifika Proğramı Sisteme Yüklenmediği İçin Sertifikaları Alınamadı
A12: MART | B12: 46043 | C12: 316 | D12: 316 | E12: 0 | F12: =E12/D12 -> 0 | G12: =$F$152+3*SQRT($F$152*(1-$F$152)/D12) -> 0.029609488 | H12: =MAX(0,$F$152-3*SQRT($F$152*(1-$F$152)/D12)) -> 0 | I12: =IF(AND(F12<=G12,F12>=H12),"KONTROL İÇİNDE"," KONTROL DIŞINDA") -> KONTROL İÇİNDE
A13: MART | B13: 46045 | C13: 9 | D13: 9 | E13: 1 | F13: =E13/D13 -> 0.11111111 | G13: =$F$152+3*SQRT($F$152*(1-$F$152)/D13) -> 0.11848464 | H13: =MAX(0,$F$152-3*SQRT($F$152*(1-$F$152)/D13)) -> 0 | I13: =IF(AND(F13<=G13,F13>=H13),"KONTROL İÇİNDE"," KONTROL DIŞINDA") -> KONTROL İÇİNDE
A14: MAYIS | B14: 46048 | C14: 2 | D14: 2 | E14: 0 | F14: =E14/D14 -> 0 | G14: =$F$152+3*SQRT($F$152*(1-$F$152)/D14) -> 0.23837528 | H14: =MAX(0,$F$152-3*SQRT($F$152*(1-$F$152)/D14)) -> 0 | I14: =IF(AND(F14<=G14,F14>=H14),"KONTROL İÇİNDE"," KONTROL DIŞINDA") -> KONTROL İÇİNDE
A15: HAZİRAN | B15: 46050 | C15: 205 | D15: 205 | E15: 0 | F15: =E15/D15 -> 0 | G15: =$F$152+3*SQRT($F$152*(1-$F$152)/D15) -> 0.033968145 | H15: =MAX(0,$F$152-3*SQRT($F$152*(1-$F$152)/D15)) -> 0 | I15: =IF(AND(F15<=G15,F15>=H15),"KONTROL İÇİNDE"," KONTROL DIŞINDA") -> KONTROL İÇİNDE
A16: HAZİRAN | B16: 46052 | C16: 6 | D16: 6 | E16: 0 | F16: =E16/D16 -> 0 | G16: =$F$152+3*SQRT($F$152*(1-$F$152)/D16) -> 0.14251417 | H16: =MAX(0,$F$152-3*SQRT($F$152*(1-$F$152)/D16)) -> 0 | I16: =IF(AND(F16<=G16,F16>=H16),"KONTROL İÇİNDE"," KONTROL DIŞINDA") -> KONTROL İÇİNDE
B17: 46055 | C17: 47 | D17: 47 | E17: 2 | F17: =E17/D17 -> 0.042553191 | G17: =$F$152+3*SQRT($F$152*(1-$F$152)/D17) -> 0.05835276 | H17: =MAX(0,$F$152-3*SQRT($F$152*(1-$F$152)/D17)) -> 0 | I17: =IF(AND(F17<=G17,F17>=H17),"KONTROL İÇİNDE"," KONTROL DIŞINDA") -> KONTROL İÇİNDE
B18: 46056 | C18: 1 | D18: 1 | E18: 0 | F18: =E18/D18 -> 0 | G18: =$F$152+3*SQRT($F$152*(1-$F$152)/D18) -> 0.33232298 | H18: =MAX(0,$F$152-3*SQRT($F$152*(1-$F$152)/D18)) -> 0 | I18: =IF(AND(F18<=G18,F18>=H18),"KONTROL İÇİNDE"," KONTROL DIŞINDA") -> KONTROL İÇİNDE
B19: 46057 | C19: 7 | D19: 7 | E19: 0 | F19: =E19/D19 -> 0 | G19: =$F$152+3*SQRT($F$152*(1-$F$152)/D19) -> 0.13280041 | H19: =MAX(0,$F$152-3*SQRT($F$152*(1-$F$152)/D19)) -> 0 | I19: =IF(AND(F19<=G19,F19>=H19),"KONTROL İÇİNDE"," KONTROL DIŞINDA") -> KONTROL İÇİNDE
B20: 46058 | C20: 6 | D20: 6 | E20: 0 | F20: =E20/D20 -> 0 | G20: =$F$152+3*SQRT($F$152*(1-$F$152)/D20) -> 0.14251417 | H20: =MAX(0,$F$152-3*SQRT($F$152*(1-$F$152)/D20)) -> 0 | I20: =IF(AND(F20<=G20,F20>=H20),"KONTROL İÇİNDE"," KONTROL DIŞINDA") -> KONTROL İÇİNDE
B21: 46059 | C21: 7 | D21: 7 | E21: 0 | F21: =E21/D21 -> 0 | G21: =$F$152+3*SQRT($F$152*(1-$F$152)/D21) -> 0.13280041 | H21: =MAX(0,$F$152-3*SQRT($F$152*(1-$F$152)/D21)) -> 0 | I21: =IF(AND(F21<=G21,F21>=H21),"KONTROL İÇİNDE"," KONTROL DIŞINDA") -> KONTROL İÇİNDE
B22: 46062 | C22: 45 | D22: 45 | E22: 1 | F22: =E22/D22 -> 0.022222222 | G22: =$F$152+3*SQRT($F$152*(1-$F$152)/D22) -> 0.059381175 | H22: =MAX(0,$F$152-3*SQRT($F$152*(1-$F$152)/D22)) -> 0 | I22: =IF(AND(F22<=G22,F22>=H22),"KONTROL İÇİNDE"," KONTROL DIŞINDA") -> KONTROL İÇİNDE
B23: 46063 | C23: 4 | D23: 4 | E23: 0 | F23: =E23/D23 -> 0 | G23: =$F$152+3*SQRT($F$152*(1-$F$152)/D23) -> 0.17194422 | H23: =MAX(0,$F$152-3*SQRT($F$152*(1-$F$152)/D23)) -> 0 | I23: =IF(AND(F23<=G23,F23>=H23),"KONTROL İÇİNDE"," KONTROL DIŞINDA") -> KONTROL İÇİNDE
B24: 46064 | C24: 2 | D24: 2 | E24: 0 | F24: =E24/D24 -> 0 | G24: =$F$152+3*SQRT($F$152*(1-$F$152)/D24) -> 0.23837528 | H24: =MAX(0,$F$152-3*SQRT($F$152*(1-$F$152)/D24)) -> 0 | I24: =IF(AND(F24<=G24,F24>=H24),"KONTROL İÇİNDE"," KONTROL DIŞINDA") -> KONTROL İÇİNDE
B25: 46065 | C25: 86 | D25: 86 | E25: 0 | F25: =E25/D25 -> 0 | G25: =$F$152+3*SQRT($F$152*(1-$F$152)/D25) -> 0.04615364 | H25: =MAX(0,$F$152-3*SQRT($F$152*(1-$F$152)/D25)) -> 0 | I25: =IF(AND(F25<=G25,F25>=H25),"KONTROL İÇİNDE"," KONTROL DIŞINDA") -> KONTROL İÇİNDE
B26: 46066 | C26: 16 | D26: 16 | E26: 0 | F26: =E26/D26 -> 0 | G26: =$F$152+3*SQRT($F$152*(1-$F$152)/D26) -> 0.091754846 | H26: =MAX(0,$F$152-3*SQRT($F$152*(1-$F$152)/D26)) -> 0 | I26: =IF(AND(F26<=G26,F26>=H26),"KONTROL İÇİNDE"," KONTROL DIŞINDA") -> KONTROL İÇİNDE
B27: 46069 | C27: 7 | D27: 7 | E27: 0 | F27: =E27/D27 -> 0 | G27: =$F$152+3*SQRT($F$152*(1-$F$152)/D27) -> 0.13280041 | H27: =MAX(0,$F$152-3*SQRT($F$152*(1-$F$152)/D27)) -> 0 | I27: =IF(AND(F27<=G27,F27>=H27),"KONTROL İÇİNDE"," KONTROL DIŞINDA") -> KONTROL İÇİNDE
B28: 46070 | C28: 11 | D28: 11 | E28: 0 | F28: =E28/D28 -> 0 | G28: =$F$152+3*SQRT($F$152*(1-$F$152)/D28) -> 0.1082775 | H28: =MAX(0,$F$152-3*SQRT($F$152*(1-$F$152)/D28)) -> 0 | I28: =IF(AND(F28<=G28,F28>=H28),"KONTROL İÇİNDE"," KONTROL DIŞINDA") -> KONTROL İÇİNDE
... B35: 46081 | C35: 28 | D35: 28 | E35: 0 | F35: =E35/D35 -> 0 | G35: =$F$152+3*SQRT($F$152*(1-$F$152)/D35) -> 0.07218294 | H35: =MAX(0,$F$152-3*SQRT($F$152*(1-$F$152)/D35)) -> 0 | I35: =IF(AND(F35<=G35,F35>=H35),"KONTROL İÇİNDE"," KONTROL DIŞINDA") -> KONTROL İÇİNDE
B36: 46083 | C36: 7 | D36: 7 | E36: 1 | F36: =E36/D36 -> 0.14285714 | G36: =$F$152+3*SQRT($F$152*(1-$F$152)/D36) -> 0.13280041 | H36: =MAX(0,$F$152-3*SQRT($F$152*(1-$F$152)/D36)) -> 0 | I36: =IF(AND(F36<=G36,F36>=H36),"KONTROL İÇİNDE"," KONTROL DIŞINDA") -> KONTROL DIŞINDA | J36: Mekanik Yapıda Çizikler Var
B37: 46084 | C37: 197 | D37: 197 | E37: 5 | F37: =E37/D37 -> 0.025380711 | G37: =$F$152+3*SQRT($F$152*(1-$F$152)/D37) -> 0.034418495 | H37: =MAX(0,$F$152-3*SQRT($F$152*(1-$F$152)/D37)) -> 0 | I37: =IF(AND(F37<=G37,F37>=H37),"KONTROL İÇİNDE"," KONTROL DIŞINDA") -> KONTROL İÇİNDE
B38: 46086 | C38: 5 | D38: 5 | E38: 0 | F38: =E38/D38 -> 0 | G38: =$F$152+3*SQRT($F$152*(1-$F$152)/D38) -> 0.15501259 | H38: =MAX(0,$F$152-3*SQRT($F$152*(1-$F$152)/D38)) -> 0 | I38: =IF(AND(F38<=G38,F38>=H38),"KONTROL İÇİNDE"," KONTROL DIŞINDA") -> KONTROL İÇİNDE
B39: 46087 | C39: 2 | D39: 2 | E39: 0 | F39: =E39/D39 -> 0 | G39: =$F$152+3*SQRT($F$152*(1-$F$152)/D39) -> 0.23837528 | H39: =MAX(0,$F$152-3*SQRT($F$152*(1-$F$152)/D39)) -> 0 | I39: =IF(AND(F39<=G39,F39>=H39),"KONTROL İÇİNDE"," KONTROL DIŞINDA") -> KONTROL İÇİNDE
B40: 46090 | C40: 2 | D40: 2 | E40: 0 | F40: =E40/D40 -> 0 | G40: =$F$152+3*SQRT($F$152*(1-$F$152)/D40) -> 0.23837528 | H40: =MAX(0,$F$152-3*SQRT($F$152*(1-$F$152)/D40)) -> 0 | I40: =IF(AND(F40<=G40,F40>=H40),"KONTROL İÇİNDE"," KONTROL DIŞINDA") -> KONTROL İÇİNDE
B41: 46091 | C41: 32 | D41: 32 | E41: 3 | F41: =E41/D41 -> 0.09375 | G41: =$F$152+3*SQRT($F$152*(1-$F$152)/D41) -> 0.068267921 | H41: =MAX(0,$F$152-3*SQRT($F$152*(1-$F$152)/D41)) -> 0 | I41: =IF(AND(F41<=G41,F41>=H41),"KONTROL İÇİNDE"," KONTROL DIŞINDA") -> KONTROL DIŞINDA | J41: Cam Kırık
B42: 46092 | C42: 9 | D42: 9 | E42: 0 | F42: =E42/D42 -> 0 | G42: =$F$152+3*SQRT($F$152*(1-$F$152)/D42) -> 0.11848464 | H42: =MAX(0,$F$152-3*SQRT($F$152*(1-$F$152)/D42)) -> 0 | I42: =IF(AND(F42<=G42,F42>=H42),"KONTROL İÇİNDE"," KONTROL DIŞINDA") -> KONTROL İÇİNDE
B43: 46093 | C43: 23 | D43: 23 | E43: 0 | F43: =E43/D43 -> 0 | G43: =$F$152+3*SQRT($F$152*(1-$F$152)/D43) -> 0.078448033 | H43: =MAX(0,$F$152-3*SQRT($F$152*(1-$F$152)/D43)) -> 0 | I43: =IF(AND(F43<=G43,F43>=H43),"KONTROL İÇİNDE"," KONTROL DIŞINDA") -> KONTROL İÇİNDE
B44: 46094 | C44: 1 | D44: 1 | E44: 0 | F44: =E44/D44 -> 0 | G44: =$F$152+3*SQRT($F$152*(1-$F$152)/D44) -> 0.33232298 | H44: =MAX(0,$F$152-3*SQRT($F$152*(1-$F$152)/D44)) -> 0 | I44: =IF(AND(F44<=G44,F44>=H44),"KONTROL İÇİNDE"," KONTROL DIŞINDA") -> KONTROL İÇİNDE
B45: 46096 | C45: 1 | D45: 1 | E45: 0 | F45: =E45/D45 -> 0 | G45: =$F$152+3*SQRT($F$152*(1-$F$152)/D45) -> 0.33232298 | H45: =MAX(0,$F$152-3*SQRT($F$152*(1-$F$152)/D45)) -> 0 | I45: =IF(AND(F45<=G45,F45>=H45),"KONTROL İÇİNDE"," KONTROL DIŞINDA") -> KONTROL İÇİNDE
B46: 46097 | C46: 33 | D46: 33 | E46: 0 | F46: =E46/D46 -> 0 | G46: =$F$152+3*SQRT($F$152*(1-$F$152)/D46) -> 0.067402184 | H46: =MAX(0,$F$152-3*SQRT($F$152*(1-$F$152)/D46)) -> 0 | I46: =IF(AND(F46<=G46,F46>=H46),"KONTROL İÇİNDE"," KONTROL DIŞINDA") -> KONTROL İÇİNDE
...

Sheet Dizgi Lehim Hatası
A1: KONTROL TARİHİ | B1: KONTROL EDİLEN ÜRÜN ADEDİ | C1: HATALI ÜRÜN ADEDİ | D1: P BAR | E1: UCL | F1: LCL | G1: KONTROL
A2: 46029 | B2: 5 | C2: 1 | D2: =C2/B2 -> 0.2 | E2: =$D$151+3*SQRT($D$151*(1-$D$151)/B2) -> 0.12873989 | F2: =MAX(0,$D$151-3*SQRT($D$151*(1-$D$151)/B2)) -> 0 | G2: =IF(AND(D2<=E2,D2>=F2),"KONTROL İÇİNDE"," KONTROL DIŞINDA") -> KONTROL DIŞINDA | H2: Erkek konnektörde lehim hatası
A3: 46030 | B3: 34 | C3: 0 | D3: =C3/B3 -> 0 | E3: =$D$151+3*SQRT($D$151*(1-$D$151)/B3) -> 0.054391502 | F3: =MAX(0,$D$151-3*SQRT($D$151*(1-$D$151)/B3)) -> 0 | G3: =IF(AND(D3<=E3,D3>=F3),"KONTROL İÇİNDE"," KONTROL DIŞINDA") -> KONTROL İÇİNDE
A4: 46031 | B4: 1 | C4: 0 | D4: =C4/B4 -> 0 | E4: =$D$151+3*SQRT($D$151*(1-$D$151)/B4) -> 0.27780243 | F4: =MAX(0,$D$151-3*SQRT($D$151*(1-$D$151)/B4)) -> 0 | G4: =IF(AND(D4<=E4,D4>=F4),"KONTROL İÇİNDE"," KONTROL DIŞINDA") -> KONTROL İÇİNDE
A5: 46034 | B5: 1 | C5: 1 | D5: =C5/B5 -> 1 | E5: =$D$151+3*SQRT($D$151*(1-$D$151)/B5) -> 0.27780243 | F5: =MAX(0,$D$151-3*SQRT($D$151*(1-$D$151)/B5)) -> 0 | G5: =IF(AND(D5<=E5,D5>=F5),"KONTROL İÇİNDE"," KONTROL DIŞINDA") -> KONTROL DIŞINDA | H5: Taş Direnç Takılı Değil
A6: 46035 | B6: 81 | C6: 0 | D6: =C6/B6 -> 0 | E6: =$D$151+3*SQRT($D$151*(1-$D$151)/B6) -> 0.038107618 | F6: =MAX(0,$D$151-3*SQRT($D$151*(1-$D$151)/B6)) -> 0 | G6: =IF(AND(D6<=E6,D6>=F6),"KONTROL İÇİNDE"," KONTROL DIŞINDA") -> KONTROL İÇİNDE
A7: 46037 | B7: 6 | C7: 0 | D7: =C7/B7 -> 0 | E7: =$D$151+3*SQRT($D$151*(1-$D$151)/B7) -> 0.11823264 | F7: =MAX(0,$D$151-3*SQRT($D$151*(1-$D$151)/B7)) -> 0 | G7: =IF(AND(D7<=E7,D7>=F7),"KONTROL İÇİNDE"," KONTROL DIŞINDA") -> KONTROL İÇİNDE
A8: 46038 | B8: 5 | C8: 1 | D8: =C8/B8 -> 0.2 | E8: =$D$151+3*SQRT($D$151*(1-$D$151)/B8) -> 0.12873989 | F8: =MAX(0,$D$151-3*SQRT($D$151*(1-$D$151)/B8)) -> 0 | G8: =IF(AND(D8<=E8,D8>=F8),"KONTROL İÇİNDE"," KONTROL DIŞINDA") -> KONTROL DIŞINDA | H8: Taş Direnç Takılmamış
A9: 46041 | B9: 12 | C9: 0 | D9: =C9/B9 -> 0 | E9: =$D$151+3*SQRT($D$151*(1-$D$151)/B9) -> 0.08598894 | F9: =MAX(0,$D$151-3*SQRT($D$151*(1-$D$151)/B9)) -> 0 | G9: =IF(AND(D9<=E9,D9>=F9),"KONTROL İÇİNDE"," KONTROL DIŞINDA") -> KONTROL İÇİNDE
A10: 46043 | B10: 316 | C10: 0 | D10: =C10/B10 -> 0 | E10: =$D$151+3*SQRT($D$151*(1-$D$151)/B10) -> 0.023315139 | F10: =MAX(0,$D$151-3*SQRT($D$151*(1-$D$151)/B10)) -> 0 | G10: =IF(AND(D10<=E10,D10>=F10),"KONTROL İÇİNDE"," KONTROL DIŞINDA") -> KONTROL İÇİNDE
A11: 46045 | B11: 9 | C11: 1 | D11: =C11/B11 -> 0.11111111 | E11: =$D$151+3*SQRT($D$151*(1-$D$151)/B11) -> 0.09803132 | F11: =MAX(0,$D$151-3*SQRT($D$151*(1-$D$151)/B11)) -> 0 | G11: =IF(AND(D11<=E11,D11>=F11),"KONTROL İÇİNDE"," KONTROL DIŞINDA") -> KONTROL DIŞINDA
A12: 46048 | B12: 2 | C12: 0 | D12: =C12/B12 -> 0 | E12: =$D$151+3*SQRT($D$151*(1-$D$151)/B12) -> 0.19882182 | F12: =MAX(0,$D$151-3*SQRT($D$151*(1-$D$151)/B12)) -> 0 | G12: =IF(AND(D12<=E12,D12>=F12),"KONTROL İÇİNDE"," KONTROL DIŞINDA") -> KONTROL İÇİNDE
A13: 46050 | B13: 205 | C13: 0 | D13: =C13/B13 -> 0 | E13: =$D$151+3*SQRT($D$151*(1-$D$151)/B13) -> 0.026979405 | F13: =MAX(0,$D$151-3*SQRT($D$151*(1-$D$151)/B13)) -> 0 | G13: =IF(AND(D13<=E13,D13>=F13),"KONTROL İÇİNDE"," KONTROL DIŞINDA") -> KONTROL İÇİNDE
A14: 46052 | B14: 6 | C14: 0 | D14: =C14/B14 -> 0 | E14: =$D$151+3*SQRT($D$151*(1-$D$151)/B14) -> 0.11823264 | F14: =MAX(0,$D$151-3*SQRT($D$151*(1-$D$151)/B14)) -> 0 | G14: =IF(AND(D14<=E14,D14>=F14),"KONTROL İÇİNDE"," KONTROL DIŞINDA") -> KONTROL İÇİNDE
A15: 46055 | B15: 6 | C15: 1 | D15: =C15/B15 -> 0.16666667 | E15: =$D$151+3*SQRT($D$151*(1-$D$151)/B15) -> 0.11823264 | F15: =MAX(0,$D$151-3*SQRT($D$151*(1-$D$151)/B15)) -> 0 | G15: =IF(AND(D15<=E15,D15>=F15),"KONTROL İÇİNDE"," KONTROL DIŞINDA") -> KONTROL DIŞINDA | H15: Entegre Bacağı Lehimlenmemiş Ayrıca Lehimler Çok Kötü
A16: 46056 | B16: 1 | C16: 0 | D16: =C16/B16 -> 0 | E16: =$D$151+3*SQRT($D$151*(1-$D$151)/B16) -> 0.27780243 | F16: =MAX(0,$D$151-3*SQRT($D$151*(1-$D$151)/B16)) -> 0 | G16: =IF(AND(D16<=E16,D16>=F16),"KONTROL İÇİNDE"," KONTROL DIŞINDA") -> KONTROL İÇİNDE
A17: 46057 | B17: 7 | C17: 0 | D17: =C17/B17 -> 0 | E17: =$D$151+3*SQRT($D$151*(1-$D$151)/B17) -> 0.1100664 | F17: =MAX(0,$D$151-3*SQRT($D$151*(1-$D$151)/B17)) -> 0 | G17: =IF(AND(D17<=E17,D17>=F17),"KONTROL İÇİNDE"," KONTROL DIŞINDA") -> KONTROL İÇİNDE
A18: 46058 | B18: 6 | C18: 0 | D18: =C18/B18 -> 0 | E18: =$D$151+3*SQRT($D$151*(1-$D$151)/B18) -> 0.11823264 | F18: =MAX(0,$D$151-3*SQRT($D$151*(1-$D$151)/B18)) -> 0 | G18: =IF(AND(D18<=E18,D18>=F18),"KONTROL İÇİNDE"," KONTROL DIŞINDA") -> KONTROL İÇİNDE
A19: 46059 | B19: 7 | C19: 0 | D19: =C19/B19 -> 0 | E19: =$D$151+3*SQRT($D$151*(1-$D$151)/B19) -> 0.1100664 | F19: =MAX(0,$D$151-3*SQRT($D$151*(1-$D$151)/B19)) -> 0 | G19: =IF(AND(D19<=E19,D19>=F19),"KONTROL İÇİNDE"," KONTROL DIŞINDA") -> KONTROL İÇİNDE
A20: 46062 | B20: 85 | C20: 9 | D20: =C20/B20 -> 0.10588235 | E20: =$D$151+3*SQRT($D$151*(1-$D$151)/B20) -> 0.037394138 | F20: =MAX(0,$D$151-3*SQRT($D$151*(1-$D$151)/B20)) -> 0 | G20: =IF(AND(D20<=E20,D20>=F20),"KONTROL İÇİNDE"," KONTROL DIŞINDA") -> KONTROL DIŞINDA | H20: Dizgiden Gelen Step Motorlar Çalışmıyor, Komponentler Düzgün Dizilmemiş Klemens Plastiği Erimiş, Dizgiden Gelen Kart Çalışmıyor
A21: 46063 | B21: 24 | C21: 1 | D21: =C21/B21 -> 0.041666667 | E21: =$D$151+3*SQRT($D$151*(1-$D$151)/B21) -> 0.063189202 | F21: =MAX(0,$D$151-3*SQRT($D$151*(1-$D$151)/B21)) -> 0 | G21: =IF(AND(D21<=E21,D21>=F21),"KONTROL İÇİNDE"," KONTROL DIŞINDA") -> KONTROL İÇİNDE
A22: 46064 | B22: 2 | C22: 0 | D22: =C22/B22 -> 0 | E22: =$D$151+3*SQRT($D$151*(1-$D$151)/B22) -> 0.19882182 | F22: =MAX(0,$D$151-3*SQRT($D$151*(1-$D$151)/B22)) -> 0 | G22: =IF(AND(D22<=E22,D22>=F22),"KONTROL İÇİNDE"," KONTROL DIŞINDA") -> KONTROL İÇİNDE
A23: 46065 | B23: 86 | C23: 0 | D23: =C23/B23 -> 0 | E23: =$D$151+3*SQRT($D$151*(1-$D$151)/B23) -> 0.037223592 | F23: =MAX(0,$D$151-3*SQRT($D$151*(1-$D$151)/B23)) -> 0 | G23: =IF(AND(D23<=E23,D23>=F23),"KONTROL İÇİNDE"," KONTROL DIŞINDA") -> KONTROL İÇİNDE
A24: 46066 | B24: 16 | C24: 0 | D24: =C24/B24 -> 0 | E24: =$D$151+3*SQRT($D$151*(1-$D$151)/B24) -> 0.075559932 | F24: =MAX(0,$D$151-3*SQRT($D$151*(1-$D$151)/B24)) -> 0 | G24: =IF(AND(D24<=E24,D24>=F24),"KONTROL İÇİNDE"," KONTROL DIŞINDA") -> KONTROL İÇİNDE
A25: 46067 | B25: 1 | C25: 1 | D25: =C25/B25 -> 1 | E25: =$D$151+3*SQRT($D$151*(1-$D$151)/B25) -> 0.27780243 | F25: =MAX(0,$D$151-3*SQRT($D$151*(1-$D$151)/B25)) -> 0 | G25: =IF(AND(D25<=E25,D25>=F25),"KONTROL İÇİNDE"," KONTROL DIŞINDA") -> KONTROL DIŞINDA | H25: Taş Direnç Takılmamış
A26: 46069 | B26: 7 | C26: 0 | D26: =C26/B26 -> 0 | E26: =$D$151+3*SQRT($D$151*(1-$D$151)/B26) -> 0.1100664 | F26: =MAX(0,$D$151-3*SQRT($D$151*(1-$D$151)/B26)) -> 0 | G26: =IF(AND(D26<=E26,D26>=F26),"KONTROL İÇİNDE"," KONTROL DIŞINDA") -> KONTROL İÇİNDE
A27: 46070 | B27: 11 | C27: 0 | D27: =C27/B27 -> 0 | E27: =$D$151+3*SQRT($D$151*(1-$D$151)/B27) -> 0.089450309 | F27: =MAX(0,$D$151-3*SQRT($D$151*(1-$D$151)/B27)) -> 0 | G27: =IF(AND(D27<=E27,D27>=F27),"KONTROL İÇİNDE"," KONTROL DIŞINDA") -> KONTROL İÇİNDE
A28: 46071 | B28: 6 | C28: 0 | D28: =C28/B28 -> 0 | E28: =$D$151+3*SQRT($D$151*(1-$D$151)/B28) -> 0.11823264 | F28: =MAX(0,$D$151-3*SQRT($D$151*(1-$D$151)/B28)) -> 0 | G28: =IF(AND(D28<=E28,D28>=F28),"KONTROL İÇİNDE"," KONTROL DIŞINDA") -> KONTROL İÇİNDE
A29: 46072 | B29: 8 | C29: 0 | D29: =C29/B29 -> 0 | E29: =$D$151+3*SQRT($D$151*(1-$D$151)/B29) -> 0.10348379 | F29: =MAX(0,$D$151-3*SQRT($D$151*(1-$D$151)/B29)) -> 0 | G29: =IF(AND(D29<=E29,D29>=F29),"KONTROL İÇİNDE"," KONTROL DIŞINDA") -> KONTROL İÇİNDE
A30: 46076 | B30: 12 | C30: 0 | D30: =C30/B30 -> 0 | E30: =$D$151+3*SQRT($D$151*(1-$D$151)/B30) -> 0.08598894 | F30: =MAX(0,$D$151-3*SQRT($D$151*(1-$D$151)/B30)) -> 0 | G30: =IF(AND(D30<=E30,D30>=F30),"KONTROL İÇİNDE"," KONTROL DIŞINDA") -> KONTROL İÇİNDE
A31: 46077 | B31: 5 | C31: 0 | D31: =C31/B31 -> 0 | E31: =$D$151+3*SQRT($D$151*(1-$D$151)/B31) -> 0.12873989 | F31: =MAX(0,$D$151-3*SQRT($D$151*(1-$D$151)/B31)) -> 0 | G31: =IF(AND(D31<=E31,D31>=F31),"KONTROL İÇİNDE"," KONTROL DIŞINDA") -> KONTROL İÇİNDE
A32: 46078 | B32: 3 | C32: 0 | D32: =C32/B32 -> 0 | E32: =$D$151+3*SQRT($D$151*(1-$D$151)/B32) -> 0.16383211 | F32: =MAX(0,$D$151-3*SQRT($D$151*(1-$D$151)/B32)) -> 0 | G32: =IF(AND(D32<=E32,D32>=F32),"KONTROL İÇİNDE"," KONTROL DIŞINDA") -> KONTROL İÇİNDE
A33: 46079 | B33: 2 | C33: 0 | D33: =C33/B33 -> 0 | E33: =$D$151+3*SQRT($D$151*(1-$D$151)/B33) -> 0.19882182 | F33: =MAX(0,$D$151-3*SQRT($D$151*(1-$D$151)/B33)) -> 0 | G33: =IF(AND(D33<=E33,D33>=F33),"KONTROL İÇİNDE"," KONTROL DIŞINDA") -> KONTROL İÇİNDE
A34: 46080 | B34: 1 | C34: 1 | D34: =C34/B34 -> 1 | E34: =$D$151+3*SQRT($D$151*(1-$D$151)/B34) -> 0.27780243 | F34: =MAX(0,$D$151-3*SQRT($D$151*(1-$D$151)/B34)) -> 0 | G34: =IF(AND(D34<=E34,D34>=F34),"KONTROL İÇİNDE"," KONTROL DIŞINDA") -> KONTROL DIŞINDA | H34: Taş Direnç Takılmamış
A35: 46081 | B35: 28 | C35: 0 | D35: =C35/B35 -> 0 | E35: =$D$151+3*SQRT($D$151*(1-$D$151)/B35) -> 0.059106085 | F35: =MAX(0,$D$151-3*SQRT($D$151*(1-$D$151)/B35)) -> 0 | G35: =IF(AND(D35<=E35,D35>=F35),"KONTROL İÇİNDE"," KONTROL DIŞINDA") -> KONTROL İÇİNDE
A36: 46083 | B36: 2 | C36: 0 | D36: =C36/B36 -> 0 | E36: =$D$151+3*SQRT($D$151*(1-$D$151)/B36) -> 0.19882182 | F36: =MAX(0,$D$151-3*SQRT($D$151*(1-$D$151)/B36)) -> 0 | G36: =IF(AND(D36<=E36,D36>=F36),"KONTROL İÇİNDE"," KONTROL DIŞINDA") -> KONTROL İÇİNDE
A37: 46084 | B37: 206 | C37: 7 | D37: =C37/B37 -> 0.033980583 | E37: =$D$151+3*SQRT($D$151*(1-$D$151)/B37) -> 0.026933636 | F37: =MAX(0,$D$151-3*SQRT($D$151*(1-$D$151)/B37)) -> 0 | G37: =IF(AND(D37<=E37,D37>=F37),"KONTROL İÇİNDE"," KONTROL DIŞINDA") -> KONTROL DIŞINDA | H37: Taş Direnç Takılmamış, Taş Direnç Lehimleri Kopmuş
A38: 46086 | B38: 5 | C38: 0 | D38: =C38/B38 -> 0 | E38: =$D$151+3*SQRT($D$151*(1-$D$151)/B38) -> 0.12873989 | F38: =MAX(0,$D$151-3*SQRT($D$151*(1-$D$151)/B38)) -> 0 | G38: =IF(AND(D38<=E38,D38>=F38),"KONTROL İÇİNDE"," KONTROL DIŞINDA") -> KONTROL İÇİNDE
A39: 46087 | B39: 2 | C39: 0 | D39: =C39/B39 -> 0 | E39: =$D$151+3*SQRT($D$151*(1-$D$151)/B39) -> 0.19882182 | F39: =MAX(0,$D$151-3*SQRT($D$151*(1-$D$151)/B39)) -> 0 | G39: =IF(AND(D39<=E39,D39>=F39),"KONTROL İÇİNDE"," KONTROL DIŞINDA") -> KONTROL İÇİNDE
A40: 46090 | B40: 2 | C40: 0 | D40: =C40/B40 -> 0 | E40: =$D$151+3*SQRT($D$151*(1-$D$151)/B40) -> 0.19882182 | F40: =MAX(0,$D$151-3*SQRT($D$151*(1-$D$151)/B40)) -> 0 | G40: =IF(AND(D40<=E40,D40>=F40),"KONTROL İÇİNDE"," KONTROL DIŞINDA") -> KONTROL İÇİNDE
...

Sheet Yazılım SW Hatası
A1: KONTROL TARİHİ | B1: KONTROL EDİLEN ÜRÜN ADEDİ | C1: HATALI ÜRÜN ADEDİ | D1: P BAR | E1: UCL | F1: LCL | G1: KONTROL
A2: 46029 | B2: 2 | C2: 0 | D2: =C2/B2 -> 0 | E2: =$D$148+3*SQRT($D$148*(1-$D$148)/B2) -> 0.15554613 | F2: =MAX(0,$D$148-3*SQRT($D$148*(1-$D$148)/B2)) -> 0 | G2: =IF(AND(D2<=E2,D2>=F2),"KONTROL İÇİNDE"," KONTROL DIŞINDA") -> KONTROL İÇİNDE
A3: 46030 | B3: 34 | C3: 0 | D3: =C3/B3 -> 0 | E3: =$D$148+3*SQRT($D$148*(1-$D$148)/B3) -> 0.041556861 | F3: =MAX(0,$D$148-3*SQRT($D$148*(1-$D$148)/B3)) -> 0 | G3: =IF(AND(D3<=E3,D3>=F3),"KONTROL İÇİNDE"," KONTROL DIŞINDA") -> KONTROL İÇİNDE
A4: 46031 | B4: 1 | C4: 0 | D4: =C4/B4 -> 0 | E4: =$D$148+3*SQRT($D$148*(1-$D$148)/B4) -> 0.21788029 | F4: =MAX(0,$D$148-3*SQRT($D$148*(1-$D$148)/B4)) -> 0 | G4: =IF(AND(D4<=E4,D4>=F4),"KONTROL İÇİNDE"," KONTROL DIŞINDA") -> KONTROL İÇİNDE
A5: 46035 | B5: 81 | C5: 0 | D5: =C5/B5 -> 0 | E5: =$D$148+3*SQRT($D$148*(1-$D$148)/B5) -> 0.028705071 | F5: =MAX(0,$D$148-3*SQRT($D$148*(1-$D$148)/B5)) -> 0 | G5: =IF(AND(D5<=E5,D5>=F5),"KONTROL İÇİNDE"," KONTROL DIŞINDA") -> KONTROL İÇİNDE
A6: 46037 | B6: 6 | C6: 0 | D6: =C6/B6 -> 0 | E6: =$D$148+3*SQRT($D$148*(1-$D$148)/B6) -> 0.091942436 | F6: =MAX(0,$D$148-3*SQRT($D$148*(1-$D$148)/B6)) -> 0 | G6: =IF(AND(D6<=E6,D6>=F6),"KONTROL İÇİNDE"," KONTROL DIŞINDA") -> KONTROL İÇİNDE
A7: 46038 | B7: 5 | C7: 0 | D7: =C7/B7 -> 0 | E7: =$D$148+3*SQRT($D$148*(1-$D$148)/B7) -> 0.10023511 | F7: =MAX(0,$D$148-3*SQRT($D$148*(1-$D$148)/B7)) -> 0 | G7: =IF(AND(D7<=E7,D7>=F7),"KONTROL İÇİNDE"," KONTROL DIŞINDA") -> KONTROL İÇİNDE
A8: 46041 | B8: 12 | C8: 0 | D8: =C8/B8 -> 0 | E8: =$D$148+3*SQRT($D$148*(1-$D$148)/B8) -> 0.066494623 | F8: =MAX(0,$D$148-3*SQRT($D$148*(1-$D$148)/B8)) -> 0 | G8: =IF(AND(D8<=E8,D8>=F8),"KONTROL İÇİNDE"," KONTROL DIŞINDA") -> KONTROL İÇİNDE
A9: 46043 | B9: 316 | C9: 2 | D9: =C9/B9 -> 0.0063291139 | E9: =$D$148+3*SQRT($D$148*(1-$D$148)/B9) -> 0.017030349 | F9: =MAX(0,$D$148-3*SQRT($D$148*(1-$D$148)/B9)) -> 0 | G9: =IF(AND(D9<=E9,D9>=F9),"KONTROL İÇİNDE"," KONTROL DIŞINDA") -> KONTROL İÇİNDE
A10: 46045 | B10: 400 | C10: 1 | D10: =C10/B10 -> 0.0025 | E10: =$D$148+3*SQRT($D$148*(1-$D$148)/B10) -> 0.015699275 | F10: =MAX(0,$D$148-3*SQRT($D$148*(1-$D$148)/B10)) -> 0 | G10: =IF(AND(D10<=E10,D10>=F10),"KONTROL İÇİNDE"," KONTROL DIŞINDA") -> KONTROL İÇİNDE
A11: 46048 | B11: 2 | C11: 0 | D11: =C11/B11 -> 0 | E11: =$D$148+3*SQRT($D$148*(1-$D$148)/B11) -> 0.15554613 | F11: =MAX(0,$D$148-3*SQRT($D$148*(1-$D$148)/B11)) -> 0 | G11: =IF(AND(D11<=E11,D11>=F11),"KONTROL İÇİNDE"," KONTROL DIŞINDA") -> KONTROL İÇİNDE
A12: 46050 | B12: 205 | C12: 1 | D12: =C12/B12 -> 0.0048780488 | E12: =$D$148+3*SQRT($D$148*(1-$D$148)/B12) -> 0.019922311 | F12: =MAX(0,$D$148-3*SQRT($D$148*(1-$D$148)/B12)) -> 0 | G12: =IF(AND(D12<=E12,D12>=F12),"KONTROL İÇİNDE"," KONTROL DIŞINDA") -> KONTROL İÇİNDE
A13: 46052 | B13: 200 | C13: 1 | D13: =C13/B13 -> 0.005 | E13: =$D$148+3*SQRT($D$148*(1-$D$148)/B13) -> 0.020106965 | F13: =MAX(0,$D$148-3*SQRT($D$148*(1-$D$148)/B13)) -> 0 | G13: =IF(AND(D13<=E13,D13>=F13),"KONTROL İÇİNDE"," KONTROL DIŞINDA") -> KONTROL İÇİNDE
... A147: 46262 | B147: 57 | C147: 0 | D147: =C147/B147 -> 0 | E147: =$D$148+3*SQRT($D$148*(1-$D$148)/B147) -> 0.033247147 | F147: =MAX(0,$D$148-3*SQRT($D$148*(1-$D$148)/B147)) -> 0 | G147: =IF(AND(D147<=E147,D147>=F147),"KONTROL İÇİNDE"," KONTROL DIŞINDA") -> KONTROL İÇİNDE
B148: =SUM(B2:B147) -> 5931 | C148: =SUM(C2:C147) -> 30 | D148: =C148/B148 -> 0.0050581689

Sheet Elektronik- Fonksiyon Hatası 
A1: KONTROL TARİHİ | B1: KONTROL EDİLEN ÜRÜN ADEDİ | C1: HATALI ÜRÜN ADEDİ | D1: P BAR | E1: UCL | F1: LCL | G1: KONTROL
A2: 46029 | B2: 2 | C2: 0 | D2: =C2/B2 -> 0 | E2: =$D$148+3*SQRT($D$148*(1-$D$148)/B2) -> 0.16674154 | F2: =MAX(0,$D$148-3*SQRT($D$148*(1-$D$148)/B2)) -> 0 | G2: =IF(AND(D2<=E2,D2>=F2),"KONTROL İÇİNDE"," KONTROL DIŞINDA") -> KONTROL İÇİNDE
A3: 46030 | B3: 34 | C3: 0 | D3: =C3/B3 -> 0 | E3: =$D$148+3*SQRT($D$148*(1-$D$148)/B3) -> 0.044826683 | F3: =MAX(0,$D$148-3*SQRT($D$148*(1-$D$148)/B3)) -> 0 | G3: =IF(AND(D3<=E3,D3>=F3),"KONTROL İÇİNDE"," KONTROL DIŞINDA") -> KONTROL İÇİNDE
A4: 46031 | B4: 1 | C4: 0 | D4: =C4/B4 -> 0 | E4: =$D$148+3*SQRT($D$148*(1-$D$148)/B4) -> 0.23340975 | F4: =MAX(0,$D$148-3*SQRT($D$148*(1-$D$148)/B4)) -> 0 | G4: =IF(AND(D4<=E4,D4>=F4),"KONTROL İÇİNDE"," KONTROL DIŞINDA") -> KONTROL İÇİNDE
A5: 46035 | B5: 81 | C5: 0 | D5: =C5/B5 -> 0 | E5: =$D$148+3*SQRT($D$148*(1-$D$148)/B5) -> 0.031081318 | F5: =MAX(0,$D$148-3*SQRT($D$148*(1-$D$148)/B5)) -> 0 | G5: =IF(AND(D5<=E5,D5>=F5),"KONTROL İÇİNDE"," KONTROL DIŞINDA") -> KONTROL İÇİNDE
A6: 46037 | B6: 6 | C6: 0 | D6: =C6/B6 -> 0 | E6: =$D$148+3*SQRT($D$148*(1-$D$148)/B6) -> 0.098715529 | F6: =MAX(0,$D$148-3*SQRT($D$148*(1-$D$148)/B6)) -> 0 | G6: =IF(AND(D6<=E6,D6>=F6),"KONTROL İÇİNDE"," KONTROL DIŞINDA") -> KONTROL İÇİNDE
A7: 46038 | B7: 2 | C7: 0 | D7: =C7/B7 -> 0 | E7: =$D$148+3*SQRT($D$148*(1-$D$148)/B7) -> 0.16674154 | F7: =MAX(0,$D$148-3*SQRT($D$148*(1-$D$148)/B7)) -> 0 | G7: =IF(AND(D7<=E7,D7>=F7),"KONTROL İÇİNDE"," KONTROL DIŞINDA") -> KONTROL İÇİNDE
A8: 46041 | B8: 12 | C8: 0 | D8: =C8/B8 -> 0 | E8: =$D$148+3*SQRT($D$148*(1-$D$148)/B8) -> 0.071498349 | F8: =MAX(0,$D$148-3*SQRT($D$148*(1-$D$148)/B8)) -> 0 | G8: =IF(AND(D8<=E8,D8>=F8),"KONTROL İÇİNDE"," KONTROL DIŞINDA") -> KONTROL İÇİNDE
A9: 46043 | B9: 316 | C9: 5 | D9: =C9/B9 -> 0.015822785 | E9: =$D$148+3*SQRT($D$148*(1-$D$148)/B9) -> 0.01859486 | F9: =MAX(0,$D$148-3*SQRT($D$148*(1-$D$148)/B9)) -> 0 | G9: =IF(AND(D9<=E9,D9>=F9),"KONTROL İÇİNDE"," KONTROL DIŞINDA") -> KONTROL İÇİNDE
A10: 46045 | B10: 60 | C10: 2 | D10: =C10/B10 -> 0.033333333 | E10: =$D$148+3*SQRT($D$148*(1-$D$148)/B10) -> 0.035175813 | F10: =MAX(0,$D$148-3*SQRT($D$148*(1-$D$148)/B10)) -> 0 | G10: =IF(AND(D10<=E10,D10>=F10),"KONTROL İÇİNDE"," KONTROL DIŞINDA") -> KONTROL İÇİNDE
A11: 46048 | B11: 2 | C11: 0 | D11: =C11/B11 -> 0 | E11: =$D$148+3*SQRT($D$148*(1-$D$148)/B11) -> 0.16674154 | F11: =MAX(0,$D$148-3*SQRT($D$148*(1-$D$148)/B11)) -> 0 | G11: =IF(AND(D11<=E11,D11>=F11),"KONTROL İÇİNDE"," KONTROL DIŞINDA") -> KONTROL İÇİNDE
A12: 46050 | B12: 205 | C12: 0 | D12: =C12/B12 -> 0 | E12: =$D$148+3*SQRT($D$148*(1-$D$148)/B12) -> 0.021687898 | F12: =MAX(0,$D$148-3*SQRT($D$148*(1-$D$148)/B12)) -> 0 | G12: =IF(AND(D12<=E12,D12>=F12),"KONTROL İÇİNDE"," KONTROL DIŞINDA") -> KONTROL İÇİNDE
A13: 46052 | B13: 6 | C13: 0 | D13: =C13/B13 -> 0 | E13: =$D$148+3*SQRT($D$148*(1-$D$148)/B13) -> 0.098715529 | F13: =MAX(0,$D$148-3*SQRT($D$148*(1-$D$148)/B13)) -> 0 | G13: =IF(AND(D13<=E13,D13>=F13),"KONTROL İÇİNDE"," KONTROL DIŞINDA") -> KONTROL İÇİNDE
... A147: 46262 | B147: 57 | C147: 0 | D147: =C147/B147 -> 0 | E147: =$D$148+3*SQRT($D$148*(1-$D$148)/B147) -> 0.035939201 | F147: =MAX(0,$D$148-3*SQRT($D$148*(1-$D$148)/B147)) -> 0 | G147: =IF(AND(D147<=E147,D147>=F147),"KONTROL İÇİNDE"," KONTROL DIŞINDA") -> KONTROL İÇİNDE
A148: Genel Toplam | B148: 4663 | C148: 27 | D148: =C148/B148 -> 0.0057902638

Sheet Markalama etiiket hatası
A1: KONTROL TARİHİ | B1: KONTROL EDİLEN ÜRÜN ADEDİ | C1: HATALI ÜRÜN ADEDİ | D1: p | E1: ucl | F1: lcl | G1: Kontrol
A2: 46028 | B2: 4 | C2: 4 | D2: =C2/B2 -> 1 | E2: =$D$150+3*SQRT($D$150*(1-$D$150)/B2) -> 0.092892545 | F2: =MAX(0,$D$150-3*SQRT($D$150*(1-$D$150)/B2)) -> 0 | G2: =IF(AND(D2<=E2,D2>=F2),"KONTROL İÇİNDE"," KONTROL DIŞINDA") -> KONTROL DIŞINDA | H2: Piranometrelere sonradan yapılan yazılım güncellemesinden dolayı sw değerleri ürünün içinde başka etiket ve markalamada bakadır Gülbahar Güven onayı ile gitmiştir
A3: 46029 | B3: 2 | C3: 0 | D3: =C3/B3 -> 0 | E3: =$D$150+3*SQRT($D$150*(1-$D$150)/B3) -> 0.1298955 | F3: =MAX(0,$D$150-3*SQRT($D$150*(1-$D$150)/B3)) -> 0 | G3: =IF(AND(D3<=E3,D3>=F3),"KONTROL İÇİNDE"," KONTROL DIŞINDA") -> KONTROL İÇİNDE
A4: 46030 | B4: 34 | C4: 0 | D4: =C4/B4 -> 0 | E4: =$D$150+3*SQRT($D$150*(1-$D$150)/B4) -> 0.034200489 | F4: =MAX(0,$D$150-3*SQRT($D$150*(1-$D$150)/B4)) -> 0 | G4: =IF(AND(D4<=E4,D4>=F4),"KONTROL İÇİNDE"," KONTROL DIŞINDA") -> KONTROL İÇİNDE
A5: 46031 | B5: 1 | C5: 0 | D5: =C5/B5 -> 0 | E5: =$D$150+3*SQRT($D$150*(1-$D$150)/B5) -> 0.18222558 | F5: =MAX(0,$D$150-3*SQRT($D$150*(1-$D$150)/B5)) -> 0 | G5: =IF(AND(D5<=E5,D5>=F5),"KONTROL İÇİNDE"," KONTROL DIŞINDA") -> KONTROL İÇİNDE
A6: 46035 | B6: 81 | C6: 0 | D6: =C6/B6 -> 0 | E6: =$D$150+3*SQRT($D$150*(1-$D$150)/B6) -> 0.023411296 | F6: =MAX(0,$D$150-3*SQRT($D$150*(1-$D$150)/B6)) -> 0 | G6: =IF(AND(D6<=E6,D6>=F6),"KONTROL İÇİNDE"," KONTROL DIŞINDA") -> KONTROL İÇİNDE
A7: 46037 | B7: 6 | C7: 0 | D7: =C7/B7 -> 0 | E7: =$D$150+3*SQRT($D$150*(1-$D$150)/B7) -> 0.076499628 | F7: =MAX(0,$D$150-3*SQRT($D$150*(1-$D$150)/B7)) -> 0 | G7: =IF(AND(D7<=E7,D7>=F7),"KONTROL İÇİNDE"," KONTROL DIŞINDA") -> KONTROL İÇİNDE
A8: 46038 | B8: 2 | C8: 0 | D8: =C8/B8 -> 0 | E8: =$D$150+3*SQRT($D$150*(1-$D$150)/B8) -> 0.1298955 | F8: =MAX(0,$D$150-3*SQRT($D$150*(1-$D$150)/B8)) -> 0 | G8: =IF(AND(D8<=E8,D8>=F8),"KONTROL İÇİNDE"," KONTROL DIŞINDA") -> KONTROL İÇİNDE
A9: 46041 | B9: 12 | C9: 0 | D9: =C9/B9 -> 0 | E9: =$D$150+3*SQRT($D$150*(1-$D$150)/B9) -> 0.055135962 | F9: =MAX(0,$D$150-3*SQRT($D$150*(1-$D$150)/B9)) -> 0 | G9: =IF(AND(D9<=E9,D9>=F9),"KONTROL İÇİNDE"," KONTROL DIŞINDA") -> KONTROL İÇİNDE
A10: 46042 | B10: 1 | C10: 1 | D10: =C10/B10 -> 1 | E10: =$D$150+3*SQRT($D$150*(1-$D$150)/B10) -> 0.18222558 | F10: =MAX(0,$D$150-3*SQRT($D$150*(1-$D$150)/B10)) -> 0 | G10: =IF(AND(D10<=E10,D10>=F10),"KONTROL İÇİNDE"," KONTROL DIŞINDA") -> KONTROL DIŞINDA | H10: Ürünün Üzerinde 3S-IS-2-AT Markalaması Var Fakat Müşteri Harici Olarak Rüzgar Hız İstemiş Özcan Bey Müşterinin Bilgisi Olduğunu Belirtti
A11: 46043 | B11: 316 | C11: 0 | D11: =C11/B11 -> 0 | E11: =$D$150+3*SQRT($D$150*(1-$D$150)/B11) -> 0.013610262 | F11: =MAX(0,$D$150-3*SQRT($D$150*(1-$D$150)/B11)) -> 0 | G11: =IF(AND(D11<=E11,D11>=F11),"KONTROL İÇİNDE"," KONTROL DIŞINDA") -> KONTROL İÇİNDE
A12: 46045 | B12: 9 | C12: 1 | D12: =C12/B12 -> 0.11111111 | E12: =$D$150+3*SQRT($D$150*(1-$D$150)/B12) -> 0.063114867 | F12: =MAX(0,$D$150-3*SQRT($D$150*(1-$D$150)/B12)) -> 0 | G12: =IF(AND(D12<=E12,D12>=F12),"KONTROL İÇİNDE"," KONTROL DIŞINDA") -> KONTROL DIŞINDA
A13: 46048 | B13: 2 | C13: 0 | D13: =C13/B13 -> 0 | E13: =$D$150+3*SQRT($D$150*(1-$D$150)/B13) -> 0.1298955 | F13: =MAX(0,$D$150-3*SQRT($D$150*(1-$D$150)/B13)) -> 0 | G13: =IF(AND(D13<=E13,D13>=F13),"KONTROL İÇİNDE"," KONTROL DIŞINDA") -> KONTROL İÇİNDE
A14: 46050 | B14: 205 | C14: 0 | D14: =C14/B14 -> 0 | E14: =$D$150+3*SQRT($D$150*(1-$D$150)/B14) -> 0.01603809 | F14: =MAX(0,$D$150-3*SQRT($D$150*(1-$D$150)/B14)) -> 0 | G14: =IF(AND(D14<=E14,D14>=F14),"KONTROL İÇİNDE"," KONTROL DIŞINDA") -> KONTROL İÇİNDE
A15: 46052 | B15: 6 | C15: 0 | D15: =C15/B15 -> 0 | E15: =$D$150+3*SQRT($D$150*(1-$D$150)/B15) -> 0.076499628 | F15: =MAX(0,$D$150-3*SQRT($D$150*(1-$D$150)/B15)) -> 0 | G15: =IF(AND(D15<=E15,D15>=F15),"KONTROL İÇİNDE"," KONTROL DIŞINDA") -> KONTROL İÇİNDE
A16: 46055 | B16: 2 | C16: 0 | D16: =C16/B16 -> 0 | E16: =$D$150+3*SQRT($D$150*(1-$D$150)/B16) -> 0.1298955 | F16: =MAX(0,$D$150-3*SQRT($D$150*(1-$D$150)/B16)) -> 0 | G16: =IF(AND(D16<=E16,D16>=F16),"KONTROL İÇİNDE"," KONTROL DIŞINDA") -> KONTROL İÇİNDE
A17: 46056 | B17: 1 | C17: 0 | D17: =C17/B17 -> 0 | E17: =$D$150+3*SQRT($D$150*(1-$D$150)/B17) -> 0.18222558 | F17: =MAX(0,$D$150-3*SQRT($D$150*(1-$D$150)/B17)) -> 0 | G17: =IF(AND(D17<=E17,D17>=F17),"KONTROL İÇİNDE"," KONTROL DIŞINDA") -> KONTROL İÇİNDE
A18: 46057 | B18: 7 | C18: 0 | D18: =C18/B18 -> 0 | E18: =$D$150+3*SQRT($D$150*(1-$D$150)/B18) -> 0.071088937 | F18: =MAX(0,$D$150-3*SQRT($D$150*(1-$D$150)/B18)) -> 0 | G18: =IF(AND(D18<=E18,D18>=F18),"KONTROL İÇİNDE"," KONTROL DIŞINDA") -> KONTROL İÇİNDE
A19: 46058 | B19: 7 | C19: 1 | D19: =C19/B19 -> 0.14285714 | E19: =$D$150+3*SQRT($D$150*(1-$D$150)/B19) -> 0.071088937 | F19: =MAX(0,$D$150-3*SQRT($D$150*(1-$D$150)/B19)) -> 0 | G19: =IF(AND(D19<=E19,D19>=F19),"KONTROL İÇİNDE"," KONTROL DIŞINDA") -> KONTROL DIŞINDA | H19: Markalama Hatası
A20: 46059 | B20: 18 | C20: 1 | D20: =C20/B20 -> 0.055555556 | E20: =$D$150+3*SQRT($D$150*(1-$D$150)/B20) -> 0.045671507 | F20: =MAX(0,$D$150-3*SQRT($D$150*(1-$D$150)/B20)) -> 0 | G20: =IF(AND(D20<=E20,D20>=F20),"KONTROL İÇİNDE"," KONTROL DIŞINDA") -> KONTROL DIŞINDA | H20: Markalama Hatası
A21: 46062 | B21: 25 | C21: 0 | D21: =C21/B21 -> 0 | E21: =$D$150+3*SQRT($D$150*(1-$D$150)/B21) -> 0.039292724 | F21: =MAX(0,$D$150-3*SQRT($D$150*(1-$D$150)/B21)) -> 0 | G21: =IF(AND(D21<=E21,D21>=F21),"KONTROL İÇİNDE"," KONTROL DIŞINDA") -> KONTROL İÇİNDE
A22: 46063 | B22: 4 | C22: 0 | D22: =C22/B22 -> 0 | E22: =$D$150+3*SQRT($D$150*(1-$D$150)/B22) -> 0.092892545 | F22: =MAX(0,$D$150-3*SQRT($D$150*(1-$D$150)/B22)) -> 0 | G22: =IF(AND(D22<=E22,D22>=F22),"KONTROL İÇİNDE"," KONTROL DIŞINDA") -> KONTROL İÇİNDE
A23: 46064 | B23: 2 | C23: 0 | D23: =C23/B23 -> 0 | E23: =$D$150+3*SQRT($D$150*(1-$D$150)/B23) -> 0.1298955 | F23: =MAX(0,$D$150-3*SQRT($D$150*(1-$D$150)/B23)) -> 0 | G23: =IF(AND(D23<=E23,D23>=F23),"KONTROL İÇİNDE"," KONTROL DIŞINDA") -> KONTROL İÇİNDE
A24: 46065 | B24: 86 | C24: 0 | D24: =C24/B24 -> 0 | E24: =$D$150+3*SQRT($D$150*(1-$D$150)/B24) -> 0.022825568 | F24: =MAX(0,$D$150-3*SQRT($D$150*(1-$D$150)/B24)) -> 0 | G24: =IF(AND(D24<=E24,D24>=F24),"KONTROL İÇİNDE"," KONTROL DIŞINDA") -> KONTROL İÇİNDE
A25: 46066 | B25: 16 | C25: 0 | D25: =C25/B25 -> 0 | E25: =$D$150+3*SQRT($D$150*(1-$D$150)/B25) -> 0.048226028 | F25: =MAX(0,$D$150-3*SQRT($D$150*(1-$D$150)/B25)) -> 0 | G25: =IF(AND(D25<=E25,D25>=F25),"KONTROL İÇİNDE"," KONTROL DIŞINDA") -> KONTROL İÇİNDE
A26: 46069 | B26: 7 | C26: 0 | D26: =C26/B26 -> 0 | E26: =$D$150+3*SQRT($D$150*(1-$D$150)/B26) -> 0.071088937 | F26: =MAX(0,$D$150-3*SQRT($D$150*(1-$D$150)/B26)) -> 0 | G26: =IF(AND(D26<=E26,D26>=F26),"KONTROL İÇİNDE"," KONTROL DIŞINDA") -> KONTROL İÇİNDE
A27: 46070 | B27: 11 | C27: 0 | D27: =C27/B27 -> 0 | E27: =$D$150+3*SQRT($D$150*(1-$D$150)/B27) -> 0.057429357 | F27: =MAX(0,$D$150-3*SQRT($D$150*(1-$D$150)/B27)) -> 0 | G27: =IF(AND(D27<=E27,D27>=F27),"KONTROL İÇİNDE"," KONTROL DIŞINDA") -> KONTROL İÇİNDE
A28: 46071 | B28: 6 | C28: 0 | D28: =C28/B28 -> 0 | E28: =$D$150+3*SQRT($D$150*(1-$D$150)/B28) -> 0.076499628 | F28: =MAX(0,$D$150-3*SQRT($D$150*(1-$D$150)/B28)) -> 0 | G28: =IF(AND(D28<=E28,D28>=F28),"KONTROL İÇİNDE"," KONTROL DIŞINDA") -> KONTROL İÇİNDE
A29: 46072 | B29: 8 | C29: 0 | D29: =C29/B29 -> 0 | E29: =$D$150+3*SQRT($D$150*(1-$D$150)/B29) -> 0.066727505 | F29: =MAX(0,$D$150-3*SQRT($D$150*(1-$D$150)/B29)) -> 0 | G29: =IF(AND(D29<=E29,D29>=F29),"KONTROL İÇİNDE"," KONTROL DIŞINDA") -> KONTROL İÇİNDE
A30: 46076 | B30: 12 | C30: 0 | D30: =C30/B30 -> 0 | E30: =$D$150+3*SQRT($D$150*(1-$D$150)/B30) -> 0.055135962 | F30: =MAX(0,$D$150-3*SQRT($D$150*(1-$D$150)/B30)) -> 0 | G30: =IF(AND(D30<=E30,D30>=F30),"KONTROL İÇİNDE"," KONTROL DIŞINDA") -> KONTROL İÇİNDE
A31: 46077 | B31: 5 | C31: 0 | D31: =C31/B31 -> 0 | E31: =$D$150+3*SQRT($D$150*(1-$D$150)/B31) -> 0.083461405 | F31: =MAX(0,$D$150-3*SQRT($D$150*(1-$D$150)/B31)) -> 0 | G31: =IF(AND(D31<=E31,D31>=F31),"KONTROL İÇİNDE"," KONTROL DIŞINDA") -> KONTROL İÇİNDE
A32: 46078 | B32: 3 | C32: 0 | D32: =C32/B32 -> 0 | E32: =$D$150+3*SQRT($D$150*(1-$D$150)/B32) -> 0.10671241 | F32: =MAX(0,$D$150-3*SQRT($D$150*(1-$D$150)/B32)) -> 0 | G32: =IF(AND(D32<=E32,D32>=F32),"KONTROL İÇİNDE"," KONTROL DIŞINDA") -> KONTROL İÇİNDE
A33: 46079 | B33: 3 | C33: 1 | D33: =C33/B33 -> 0.33333333 | E33: =$D$150+3*SQRT($D$150*(1-$D$150)/B33) -> 0.10671241 | F33: =MAX(0,$D$150-3*SQRT($D$150*(1-$D$150)/B33)) -> 0 | G33: =IF(AND(D33<=E33,D33>=F33),"KONTROL İÇİNDE"," KONTROL DIŞINDA") -> KONTROL DIŞINDA | H33: İlk Testte Kalibrasyon Değeri Yanlış Yazıldığı İçin Markalma Yanlış Yapılmış
A34: 46081 | B34: 28 | C34: 0 | D34: =C34/B34 -> 0 | E34: =$D$150+3*SQRT($D$150*(1-$D$150)/B34) -> 0.037324224 | F34: =MAX(0,$D$150-3*SQRT($D$150*(1-$D$150)/B34)) -> 0 | G34: =IF(AND(D34<=E34,D34>=F34),"KONTROL İÇİNDE"," KONTROL DIŞINDA") -> KONTROL İÇİNDE
A35: 46083 | B35: 2 | C35: 0 | D35: =C35/B35 -> 0 | E35: =$D$150+3*SQRT($D$150*(1-$D$150)/B35) -> 0.1298955 | F35: =MAX(0,$D$150-3*SQRT($D$150*(1-$D$150)/B35)) -> 0 | G35: =IF(AND(D35<=E35,D35>=F35),"KONTROL İÇİNDE"," KONTROL DIŞINDA") -> KONTROL İÇİNDE
A36: 46084 | B36: 133 | C36: 0 | D36: =C36/B36 -> 0 | E36: =$D$150+3*SQRT($D$150*(1-$D$150)/B36) -> 0.019051823 | F36: =MAX(0,$D$150-3*SQRT($D$150*(1-$D$150)/B36)) -> 0 | G36: =IF(AND(D36<=E36,D36>=F36),"KONTROL İÇİNDE"," KONTROL DIŞINDA") -> KONTROL İÇİNDE
A37: 46086 | B37: 5 | C37: 0 | D37: =C37/B37 -> 0 | E37: =$D$150+3*SQRT($D$150*(1-$D$150)/B37) -> 0.083461405 | F37: =MAX(0,$D$150-3*SQRT($D$150*(1-$D$150)/B37)) -> 0 | G37: =IF(AND(D37<=E37,D37>=F37),"KONTROL İÇİNDE"," KONTROL DIŞINDA") -> KONTROL İÇİNDE
A38: 46087 | B38: 14 | C38: 2 | D38: =C38/B38 -> 0.14285714 | E38: =$D$150+3*SQRT($D$150*(1-$D$150)/B38) -> 0.051310026 | F38: =MAX(0,$D$150-3*SQRT($D$150*(1-$D$150)/B38)) -> 0 | G38: =IF(AND(D38<=E38,D38>=F38),"KONTROL İÇİNDE"," KONTROL DIŞINDA") -> KONTROL DIŞINDA | H38: Markalama Hatası
A39: 46090 | B39: 2 | C39: 0 | D39: =C39/B39 -> 0 | E39: =$D$150+3*SQRT($D$150*(1-$D$150)/B39) -> 0.1298955 | F39: =MAX(0,$D$150-3*SQRT($D$150*(1-$D$150)/B39)) -> 0 | G39: =IF(AND(D39<=E39,D39>=F39),"KONTROL İÇİNDE"," KONTROL DIŞINDA") -> KONTROL İÇİNDE
A40: 46091 | B40: 2 | C40: 0 | D40: =C40/B40 -> 0 | E40: =$D$150+3*SQRT($D$150*(1-$D$150)/B40) -> 0.1298955 | F40: =MAX(0,$D$150-3*SQRT($D$150*(1-$D$150)/B40)) -> 0 | G40: =IF(AND(D40<=E40,D40>=F40),"KONTROL İÇİNDE"," KONTROL DIŞINDA") -> KONTROL İÇİNDE
...

Sheet ADC Hatası
A1: KONTROL TARİHİ | B1: KONTROL EDİLEN ÜRÜN ADEDİ | C1: HATALI ÜRÜN ADEDİ | D1: p | E1: ucl | F1: lcl | G1: KONTROL
A2: 46029 | B2: 2 | C2: 0 | D2: =C2/B2 -> 0 | E2: =$D$148+3*SQRT($D$148*(1-$D$148)/B2) -> 0.12517726 | F2: =MAX(0,$D$148-3*SQRT($D$148*(1-$D$148)/B2)) -> 0 | G2: =IF(AND(D2<=E2,D2>=F2),"KONTROL İÇİNDE"," KONTROL DIŞINDA") -> KONTROL İÇİNDE
A3: 46030 | B3: 34 | C3: 0 | D3: =C3/B3 -> 0 | E3: =$D$148+3*SQRT($D$148*(1-$D$148)/B3) -> 0.032868105 | F3: =MAX(0,$D$148-3*SQRT($D$148*(1-$D$148)/B3)) -> 0 | G3: =IF(AND(D3<=E3,D3>=F3),"KONTROL İÇİNDE"," KONTROL DIŞINDA") -> KONTROL İÇİNDE
A4: 46031 | B4: 1 | C4: 0 | D4: =C4/B4 -> 0 | E4: =$D$148+3*SQRT($D$148*(1-$D$148)/B4) -> 0.17565581 | F4: =MAX(0,$D$148-3*SQRT($D$148*(1-$D$148)/B4)) -> 0 | G4: =IF(AND(D4<=E4,D4>=F4),"KONTROL İÇİNDE"," KONTROL DIŞINDA") -> KONTROL İÇİNDE
A5: 46035 | B5: 81 | C5: 0 | D5: =C5/B5 -> 0 | E5: =$D$148+3*SQRT($D$148*(1-$D$148)/B5) -> 0.022460653 | F5: =MAX(0,$D$148-3*SQRT($D$148*(1-$D$148)/B5)) -> 0 | G5: =IF(AND(D5<=E5,D5>=F5),"KONTROL İÇİNDE"," KONTROL DIŞINDA") -> KONTROL İÇİNDE
A6: 46037 | B6: 6 | C6: 0 | D6: =C6/B6 -> 0 | E6: =$D$148+3*SQRT($D$148*(1-$D$148)/B6) -> 0.073670627 | F6: =MAX(0,$D$148-3*SQRT($D$148*(1-$D$148)/B6)) -> 0 | G6: =IF(AND(D6<=E6,D6>=F6),"KONTROL İÇİNDE"," KONTROL DIŞINDA") -> KONTROL İÇİNDE
A7: 46038 | B7: 2 | C7: 0 | D7: =C7/B7 -> 0 | E7: =$D$148+3*SQRT($D$148*(1-$D$148)/B7) -> 0.12517726 | F7: =MAX(0,$D$148-3*SQRT($D$148*(1-$D$148)/B7)) -> 0 | G7: =IF(AND(D7<=E7,D7>=F7),"KONTROL İÇİNDE"," KONTROL DIŞINDA") -> KONTROL İÇİNDE
A8: 46041 | B8: 12 | C8: 0 | D8: =C8/B8 -> 0 | E8: =$D$148+3*SQRT($D$148*(1-$D$148)/B8) -> 0.053062845 | F8: =MAX(0,$D$148-3*SQRT($D$148*(1-$D$148)/B8)) -> 0 | G8: =IF(AND(D8<=E8,D8>=F8),"KONTROL İÇİNDE"," KONTROL DIŞINDA") -> KONTROL İÇİNDE
A9: 46043 | B9: 316 | C9: 0 | D9: =C9/B9 -> 0 | E9: =$D$148+3*SQRT($D$148*(1-$D$148)/B9) -> 0.013006397 | F9: =MAX(0,$D$148-3*SQRT($D$148*(1-$D$148)/B9)) -> 0 | G9: =IF(AND(D9<=E9,D9>=F9),"KONTROL İÇİNDE"," KONTROL DIŞINDA") -> KONTROL İÇİNDE
A10: 46045 | B10: 9 | C10: 1 | D10: =C10/B10 -> 0.11111111 | E10: =$D$148+3*SQRT($D$148*(1-$D$148)/B10) -> 0.060759442 | F10: =MAX(0,$D$148-3*SQRT($D$148*(1-$D$148)/B10)) -> 0 | G10: =IF(AND(D10<=E10,D10>=F10),"KONTROL İÇİNDE"," KONTROL DIŞINDA") -> KONTROL DIŞINDA
A11: 46048 | B11: 8 | C11: 1 | D11: =C11/B11 -> 0.125 | E11: =$D$148+3*SQRT($D$148*(1-$D$148)/B11) -> 0.064244259 | F11: =MAX(0,$D$148-3*SQRT($D$148*(1-$D$148)/B11)) -> 0 | G11: =IF(AND(D11<=E11,D11>=F11),"KONTROL İÇİNDE"," KONTROL DIŞINDA") -> KONTROL DIŞINDA | H11: ADC Girilmemiş
A12: 46050 | B12: 205 | C12: 0 | D12: =C12/B12 -> 0 | E12: =$D$148+3*SQRT($D$148*(1-$D$148)/B12) -> 0.015348324 | F12: =MAX(0,$D$148-3*SQRT($D$148*(1-$D$148)/B12)) -> 0 | G12: =IF(AND(D12<=E12,D12>=F12),"KONTROL İÇİNDE"," KONTROL DIŞINDA") -> KONTROL İÇİNDE
A13: 46052 | B13: 7 | C13: 1 | D13: =C13/B13 -> 0.14285714 | E13: =$D$148+3*SQRT($D$148*(1-$D$148)/B13) -> 0.068451376 | F13: =MAX(0,$D$148-3*SQRT($D$148*(1-$D$148)/B13)) -> 0 | G13: =IF(AND(D13<=E13,D13>=F13),"KONTROL İÇİNDE"," KONTROL DIŞINDA") -> KONTROL DIŞINDA | H13: ADC Değeri 12 Girilmiş Kapalı İken 7 Gösteriyor
